Workbook

Sheet daily_prices
A1: DATE | B1: NIKE | C1: SP500 | D1: Cambios Porcentuales | G1: SUMMARY OUTPUT
A2: 44200 | B2: 140.1 | C2: 3700.65 | D2: NIKE | E2: SP500
A3: 44201 | B3: 141.23 | C3: 3726.86 | D3: =(B3-B2)/B2 -> 0.0080656674 | E3: =(C3-C2)/C2 -> 0.0070825396 | G3: Regression Statistics
A4: 44202 | B4: 142.35 | C4: 3748.14 | D4: =(B4-B3)/B3 -> 0.0079303264 | E4: =(C4-C3)/C3 -> 0.0057099006 | G4: Multiple R | H4: 0.56091124 | I4: Correlacion
A5: 44203 | B5: 144.95 | C5: 3803.79 | D5: =(B5-B4)/B4 -> 0.01826484 | E5: =(C5-C4)/C4 -> 0.014847364 | G5: R Square | H5: 0.31462142 | I5: Poder de Explicacion. Quiere decir que el modelo tiene una capacidad del 31% de explicar el comportamiento de NIKE. El otro 67% lo dan otras variables de mercado o economicas.
A6: 44204 | B6: 146.35 | C6: 3824.68 | D6: =(B6-B5)/B5 -> 0.0096585029 | E6: =(C6-C5)/C5 -> 0.005491891 | G6: Adjusted R Square | H6: 0.31393741
A7: 44207 | B7: 147.05 | C7: 3799.61 | D7: =(B7-B6)/B6 -> 0.0047830543 | E7: =(C7-C6)/C6 -> -0.0065547967 | G7: Standard Error | H7: 0.017148256
A8: 44208 | B8: 145.05 | C8: 3801.19 | D8: =(B8-B7)/B7 -> -0.013600816 | E8: =(C8-C7)/C7 -> 0.00041583215 | G8: Observations | H8: 1004
A9: 44209 | B9: 143.04 | C9: 3809.84 | D9: =(B9-B8)/B8 -> -0.013857291 | E9: =(C9-C8)/C8 -> 0.0022756032
A10: 44210 | B10: 141.3 | C10: 3795.54 | D10: =(B10-B9)/B9 -> -0.01216443 | E10: =(C10-C9)/C9 -> -0.0037534385 | G10: ANOVA
A11: 44211 | B11: 140.72 | C11: 3768.25 | D11: =(B11-B10)/B10 -> -0.0041047417 | E11: =(C11-C10)/C10 -> -0.0071900178 | H11: df | I11: SS | J11: MS | K11: F | L11: Significance F
A12: 44215 | B12: 139.27 | C12: 3798.91 | D12: =(B12-B11)/B11 -> -0.01030415 | E12: =(C12-C11)/C11 -> 0.0081364028 | G12: Regression | H12: 1 | I12: 0.13525875 | J12: 0.13525875 | K12: 459.96573 | L12: 2.8363616e-84
A13: 44216 | B13: 142.8 | C13: 3851.85 | D13: =(B13-B12)/B12 -> 0.025346449 | E13: =(C13-C12)/C12 -> 0.013935576 | G13: Residual | H13: 1002 | I13: 0.29465079 | J13: 0.00029406267
A14: 44217 | B14: 141.61 | C14: 3853.07 | D14: =(B14-B13)/B13 -> -0.0083333333 | E14: =(C14-C13)/C13 -> 0.00031673092 | G14: Total | H14: 1003 | I14: 0.42990954
A15: 44218 | B15: 139.35 | C15: 3841.47 | D15: =(B15-B14)/B14 -> -0.015959325 | E15: =(C15-C14)/C14 -> -0.0030105864
A16: 44221 | B16: 137.55 | C16: 3855.36 | D16: =(B16-B15)/B15 -> -0.012917115 | E16: =(C16-C15)/C15 -> 0.0036158033 | H16: Coefficients | I16: Standard Error | J16: t Stat | K16: P-value | L16: Lower 95% | M16: Upper 95% | N16: Lower 95.0% | O16: Upper 95.0%
A17: 44222 | B17: 135.1 | C17: 3849.62 | D17: =(B17-B16)/B16 -> -0.017811705 | E17: =(C17-C16)/C16 -> -0.0014888363 | G17: Intercept | H17: -0.00097277504 | I17: 0.00054186094 | J17: -1.7952485 | K17: 0.072915375 | L17: -0.0020360874 | M17: 9.0537289e-05 | N17: -0.0020360874 | O17: 9.0537289e-05
A18: 44223 | B18: 131.02 | C18: 3750.77 | D18: =(B18-B17)/B17 -> -0.030199852 | E18: =(C18-C17)/C17 -> -0.025677859 | G18: X Variable 1 | H18: 1.117937 | I18: 0.052126024 | J18: 21.446812 | K18: 2.8363616e-84 | L18: 1.0156483 | M18: 1.2202257 | N18: 1.0156483 | O18: 1.2202257
A19: 44224 | B19: 134.72 | C19: 3787.38 | D19: =(B19-B18)/B18 -> 0.028239963 | E19: =(C19-C18)/C18 -> 0.0097606625 | H19: Beta
A20: 44225 | B20: 133.59 | C20: 3714.24 | D20: =(B20-B19)/B19 -> -0.0083877672 | E20: =(C20-C19)/C19 -> -0.019311503 | G20: Interpretacion: | K20: Por regla de dedo pordemos decir que si el Valor Absoluto de t Stat es >2 entonces
A21: 44228 | B21: 135.71 | C21: 3773.86 | D21: =(B21-B20)/B20 -> 0.015869451 | E21: =(C21-C20)/C20 -> 0.016051736 | G21: B > 1: Activo de Capital Agresivo | K21: la variable estadistica S&P500 es estadisticamente significativa para influir
A22: 44229 | B22: 139.59 | C22: 3826.31 | D22: =(B22-B21)/B21 -> 0.028590377 | E22: =(C22-C21)/C21 -> 0.013898237 | G22: por cada 1% de cambio del mercado, NIKE se mueve 1.11 | K22: e impactar el comportamiento de los cambios porcentuales de NIKE
A23: 44230 | B23: 138.63 | C23: 3830.17 | D23: =(B23-B22)/B22 -> -0.0068772835 | E23: =(C23-C22)/C22 -> 0.0010088048 | G23: veces mas que el mercado.
A24: 44231 | B24: 140.63 | C24: 3871.74 | D24: =(B24-B23)/B23 -> 0.014426892 | E24: =(C24-C23)/C23 -> 0.010853304 | G24: B > 1: Activo a la Defensiva
A25: 44232 | B25: 145.11 | C25: 3886.83 | D25: =(B25-B24)/B24 -> 0.031856645 | E25: =(C25-C24)/C24 -> 0.0038974725 | G25: por cada 1% de cambio del mercado, NIKE se mueve (por ejemplo si B=0.85) entonces 0.85
A26: 44235 | B26: 143.41 | C26: 3915.59 | D26: =(B26-B25)/B25 -> -0.01171525 | E26: =(C26-C25)/C25 -> 0.007399346 | G26: veces el mercado.
A27: 44236 | B27: 141.79 | C27: 3911.23 | D27: =(B27-B26)/B26 -> -0.011296283 | E27: =(C27-C26)/C26 -> -0.0011134976
A28: 44237 | B28: 142.46 | C28: 3909.88 | D28: =(B28-B27)/B27 -> 0.004725298 | E28: =(C28-C27)/C27 -> -0.00034515996 | G28: Usar la Funcion Regression
A29: 44238 | B29: 143.54 | C29: 3916.38 | D29: =(B29-B28)/B28 -> 0.0075810754 | E29: =(C29-C28)/C28 -> 0.0016624551
A30: 44239 | B30: 142.12 | C30: 3934.83 | D30: =(B30-B29)/B29 -> -0.0098927128 | E30: =(C30-C29)/C29 -> 0.0047109831
A31: 44243 | B31: 141.71 | C31: 3932.59 | D31: =(B31-B30)/B30 -> -0.002884886 | E31: =(C31-C30)/C30 -> -0.00056927491
A32: 44244 | B32: 143.99 | C32: 3931.33 | D32: =(B32-B31)/B31 -> 0.016089196 | E32: =(C32-C31)/C31 -> -0.00032039953 | M32: Nivel de confianza del 95% para la prueba de Hipotesis
A33: 44245 | B33: 145.09 | C33: 3913.97 | D33: =(B33-B32)/B32 -> 0.0076394194 | E33: =(C33-C32)/C32 -> -0.0044158084
A34: 44246 | B34: 142.02 | C34: 3906.71 | D34: =(B34-B33)/B33 -> -0.02115928 | E34: =(C34-C33)/C33 -> -0.0018548941
A35: 44249 | B35: 136.67 | C35: 3876.5 | D35: =(B35-B34)/B34 -> -0.037670751 | E35: =(C35-C34)/C34 -> -0.0077328494
A36: 44250 | B36: 136.13 | C36: 3881.37 | D36: =(B36-B35)/B35 -> -0.0039511231 | E36: =(C36-C35)/C35 -> 0.0012562879
A37: 44251 | B37: 135.65 | C37: 3925.43 | D37: =(B37-B36)/B36 -> -0.0035260413 | E37: =(C37-C36)/C36 -> 0.011351662
A38: 44252 | B38: 135.54 | C38: 3829.34 | D38: =(B38-B37)/B37 -> -0.00081091043 | E38: =(C38-C37)/C37 -> -0.024478847
A39: 44253 | B39: 134.78 | C39: 3811.15 | D39: =(B39-B38)/B38 -> -0.0056072008 | E39: =(C39-C38)/C38 -> -0.0047501658
A40: 44256 | B40: 137.65 | C40: 3901.82 | D40: =(B40-B39)/B39 -> 0.021293961 | E40: =(C40-C39)/C39 -> 0.023790719
...

Sheet weekly_prices
A1: DATE | B1: NIKE | C1: SP500 | D1: Cambios Porcentuales | G1: SUMMARY OUTPUT
A2: 44197 | B2: 141.47 | C2: 3756.07 | D2: NIKE | E2: SP500
A3: 44204 | B3: 146.35 | C3: 3824.68 | D3: =(B3-B2)/B2 -> 0.034494946 | E3: =(C3-C2)/C2 -> 0.018266433 | G3: Regression Statistics
A4: 44211 | B4: 140.72 | C4: 3768.25 | D4: =(B4-B3)/B3 -> -0.038469423 | E4: =(C4-C3)/C3 -> -0.014754176 | G4: Multiple R | H4: 0.53637103 | I4: Correlacion
A5: 44218 | B5: 139.35 | C5: 3841.47 | D5: =(B5-B4)/B4 -> -0.0097356453 | E5: =(C5-C4)/C4 -> 0.01943077 | G5: R Square | H5: 0.28769388 | I5: (Ligeramente mas baja que el 31% diario de Poder de explicacion)
A6: 44225 | B6: 133.59 | C6: 3714.24 | D6: =(B6-B5)/B5 -> -0.041334769 | E6: =(C6-C5)/C5 -> -0.033120134 | G6: Adjusted R Square | H6: 0.28423608
A7: 44232 | B7: 145.11 | C7: 3886.83 | D7: =(B7-B6)/B6 -> 0.086234 | E7: =(C7-C6)/C6 -> 0.04646711 | G7: Standard Error | H7: 0.038392883
A8: 44239 | B8: 142.12 | C8: 3934.83 | D8: =(B8-B7)/B7 -> -0.020605058 | E8: =(C8-C7)/C7 -> 0.012349395 | G8: Observations | H8: 208
A9: 44246 | B9: 142.02 | C9: 3906.71 | D9: =(B9-B8)/B8 -> -0.00070363073 | E9: =(C9-C8)/C8 -> -0.0071464333
A10: 44253 | B10: 134.78 | C10: 3811.15 | D10: =(B10-B9)/B9 -> -0.050978735 | E10: =(C10-C9)/C9 -> -0.02446048 | G10: ANOVA
A11: 44260 | B11: 133.35 | C11: 3841.94 | D11: =(B11-B10)/B10 -> -0.010609883 | E11: =(C11-C10)/C10 -> 0.0080789263 | H11: df | I11: SS | J11: MS | K11: F | L11: Significance F
A12: 44267 | B12: 140.45 | C12: 3943.34 | D12: =(B12-B11)/B11 -> 0.053243345 | E12: =(C12-C11)/C11 -> 0.026392916 | G12: Regression | H12: 1 | I12: 0.12264013 | J12: 0.12264013 | K12: 83.201503 | L12: 6.8337016e-17
A13: 44274 | B13: 137.49 | C13: 3913.1 | D13: =(B13-B12)/B12 -> -0.021075116 | E13: =(C13-C12)/C12 -> -0.0076686261 | G13: Residual | H13: 206 | I13: 0.30364677 | J13: 0.0014740134
A14: 44281 | B14: 132.99 | C14: 3974.54 | D14: =(B14-B13)/B13 -> -0.032729653 | E14: =(C14-C13)/C13 -> 0.015701107 | G14: Total | H14: 207 | I14: 0.4262869
A15: 44288 | B15: 132.53 | C15: 4019.87 | D15: =(B15-B14)/B14 -> -0.0034589067 | E15: =(C15-C14)/C14 -> 0.011405093
A16: 44295 | B16: 135.45 | C16: 4128.8 | D16: =(B16-B15)/B15 -> 0.022032747 | E16: =(C16-C15)/C15 -> 0.027097891 | H16: Coefficients | I16: Standard Error | J16: t Stat | K16: P-value | L16: Lower 95% | M16: Upper 95% | N16: Lower 95.0% | O16: Upper 95.0%
A17: 44302 | B17: 134.31 | C17: 4185.47 | D17: =(B17-B16)/B16 -> -0.0084163898 | E17: =(C17-C16)/C16 -> 0.013725538 | G17: Intercept | H17: -0.0046380926 | I17: 0.002678697 | J17: -1.7314734 | K17: 0.084864486 | L17: -0.0099192689 | M17: 0.00064308358 | N17: -0.0099192689 | O17: 0.00064308358
A18: 44309 | B18: 130.19 | C18: 4180.17 | D18: =(B18-B17)/B17 -> -0.030675303 | E18: =(C18-C17)/C17 -> -0.0012662855 | G18: X Variable 1 | H18: 1.0984573 | I18: 0.12042526 | J18: 9.1214858 | K18: 6.8337016e-17 | L18: 0.86103324 | M18: 1.3358813 | N18: 0.86103324 | O18: 1.3358813
A19: 44316 | B19: 132.62 | C19: 4181.17 | D19: =(B19-B18)/B18 -> 0.018665028 | E19: =(C19-C18)/C18 -> 0.00023922472 | H19: Baja con respecto a 1.1 | J19: Baja con respecto a daily
A20: 44323 | B20: 137.81 | C20: 4232.6 | D20: =(B20-B19)/B19 -> 0.039134369 | E20: =(C20-C19)/C19 -> 0.012300385 | H20: Elasticidad: precio | J20: pero sigue siendo >2
A21: 44330 | B21: 135.93 | C21: 4173.85 | D21: =(B21-B20)/B20 -> -0.013641971 | E21: =(C21-C20)/C20 -> -0.013880357 | H21: de la accion a los
A22: 44337 | B22: 132.66 | C22: 4155.86 | D22: =(B22-B21)/B21 -> -0.0240565 | E22: =(C22-C21)/C21 -> -0.0043101693 | H22: movimientos del mercado
A23: 44344 | B23: 136.46 | C23: 4204.11 | D23: =(B23-B22)/B22 -> 0.028644656 | E23: =(C23-C22)/C22 -> 0.011610112
A24: 44351 | B24: 133.74 | C24: 4229.89 | D24: =(B24-B23)/B23 -> -0.019932581 | E24: =(C24-C23)/C23 -> 0.0061320945
A25: 44358 | B25: 131.94 | C25: 4247.44 | D25: =(B25-B24)/B24 -> -0.01345895 | E25: =(C25-C24)/C24 -> 0.0041490441
A26: 44365 | B26: 128.41 | C26: 4166.45 | D26: =(B26-B25)/B25 -> -0.026754585 | E26: =(C26-C25)/C25 -> -0.019067956
A27: 44372 | B27: 154.35 | C27: 4280.7 | D27: =(B27-B26)/B26 -> 0.20200919 | E27: =(C27-C26)/C26 -> 0.027421426 | G27: Calculo del Rendimiento Esperado del Mercado E[Rm]:
A28: 44379 | B28: 159.74 | C28: 4352.34 | D28: =(B28-B27)/B27 -> 0.034920635 | E28: =(C28-C27)/C27 -> 0.016735581
A29: 44386 | B29: 161 | C29: 4369.55 | D29: =(B29-B28)/B28 -> 0.0078878177 | E29: =(C29-C28)/C28 -> 0.0039541948 | G29: Metodo 1: Por Valores historicos
A30: 44393 | B30: 159.85 | C30: 4327.16 | D30: =(B30-B29)/B29 -> -0.0071428571 | E30: =(C30-C29)/C29 -> -0.0097012278 | G30: Promedio S&P500 | H30: =AVERAGE(E3:E210) -> 0.0024747145 | I30: Rendimiento promedio semanal de las variaciones porcentuales de SP500
A31: 44400 | B31: 166.36 | C31: 4411.79 | D31: =(B31-B30)/B30 -> 0.04072568 | E31: =(C31-C30)/C30 -> 0.019557862 | I31: Ojo, este rendimiento es SEMANAL y nosotros traemos un YTM del bono de 10Y ANUAL
A32: 44407 | B32: 167.51 | C32: 4395.26 | D32: =(B32-B31)/B31 -> 0.0069127194 | E32: =(C32-C31)/C31 -> -0.0037467785
A33: 44414 | B33: 172.8 | C33: 4436.52 | D33: =(B33-B32)/B32 -> 0.031580204 | E33: =(C33-C32)/C32 -> 0.0093873855 | H33: =H30*52 -> 0.12868515 | I33: Anualizando (con los datos de 4 anios)
A34: 44421 | B34: 171.69 | C34: 4468 | D34: =(B34-B33)/B33 -> -0.0064236111 | E34: =(C34-C33)/C33 -> 0.0070956515
A35: 44428 | B35: 167.79 | C35: 4441.67 | D35: =(B35-B34)/B34 -> -0.022715359 | E35: =(C35-C34)/C34 -> -0.005893017 | G35: Metodo 2: Por Futuros del SP500
A36: 44435 | B36: 167.58 | C36: 4509.37 | D36: =(B36-B35)/B35 -> -0.0012515645 | E36: =(C36-C35)/C35 -> 0.015242015 | G36: dic2024 | H36: =C210 -> 5970.84
A37: 44442 | B37: 163.29 | C37: 4535.43 | D37: =(B37-B36)/B36 -> -0.025599714 | E37: =(C37-C36)/C36 -> 0.0057790778 | G37: Valor Esperado E[2025] | H37: 5711.5 | I37: https://www.cmegroup.com/markets/equities/sp/e-mini-sandp500.settlements.html
A38: 44449 | B38: 163.59 | C38: 4458.58 | D38: =(B38-B37)/B37 -> 0.0018372221 | E38: =(C38-C37)/C37 -> -0.016944369 | H38: =(H37-H36)/H36 -> -0.043434425 | I38: Calculo de la Variacion Porcentual Esperada
A39: 44456 | B39: 156.42 | C39: 4432.99 | D39: =(B39-B38)/B38 -> -0.043829085 | E39: =(C39-C38)/C38 -> -0.0057394955
A40: 44463 | B40: 149.59 | C40: 4455.48 | D40: =(B40-B39)/B39 -> -0.043664493 | E40: =(C40-C39)/C39 -> 0.0050733252 | G40: Usando Informacion del Mercado tendriamos un rendimiento esperado del 12.87%, pero usando informacion del Futuros
...

Sheet monthly_prices
A1: DATE | B1: NIKE | C1: SP500 | D1: Cambios Porcentuales | G1: SUMMARY OUTPUT
A2: 44227 | B2: 133.59 | C2: 3714.24 | D2: NIKE | E2: SP500
A3: 44255 | B3: 134.78 | C3: 3811.15 | D3: =(B3-B2)/B2 -> 0.0089078524 | E3: =(C3-C2)/C2 -> 0.026091475 | G3: Regression Statistics
A4: 44286 | B4: 132.89 | C4: 3972.89 | D4: =(B4-B3)/B3 -> -0.014022852 | E4: =(C4-C3)/C3 -> 0.042438634 | G4: Multiple R | H4: 0.61924068 | I4: Correlacion
A5: 44316 | B5: 132.62 | C5: 4181.17 | D5: =(B5-B4)/B4 -> -0.0020317556 | E5: =(C5-C4)/C4 -> 0.052425313 | G5: R Square | H5: 0.38345902 | I5: Sube el poder de explicacion
A6: 44347 | B6: 136.46 | C6: 4204.11 | D6: =(B6-B5)/B5 -> 0.028954909 | E6: =(C6-C5)/C5 -> 0.0054865026 | G6: Adjusted R Square | H6: 0.37087655
A7: 44377 | B7: 154.49 | C7: 4297.5 | D7: =(B7-B6)/B6 -> 0.13212663 | E7: =(C7-C6)/C6 -> 0.022213976 | G7: Standard Error | H7: 0.074001556
A8: 44408 | B8: 167.51 | C8: 4395.26 | D8: =(B8-B7)/B7 -> 0.0842773 | E8: =(C8-C7)/C7 -> 0.022748109 | G8: Observations | H8: 51
A9: 44439 | B9: 164.74 | C9: 4522.68 | D9: =(B9-B8)/B8 -> -0.016536326 | E9: =(C9-C8)/C8 -> 0.028990321
A10: 44469 | B10: 145.23 | C10: 4307.54 | D10: =(B10-B9)/B9 -> -0.11842904 | E10: =(C10-C9)/C9 -> -0.04756914 | G10: ANOVA
A11: 44500 | B11: 167.29 | C11: 4605.38 | D11: =(B11-B10)/B10 -> 0.15189699 | E11: =(C11-C10)/C10 -> 0.069143873 | H11: df | I11: SS | J11: MS | K11: F | L11: Significance F
A12: 44530 | B12: 169.24 | C12: 4567 | D12: =(B12-B11)/B11 -> 0.011656405 | E12: =(C12-C11)/C11 -> -0.0083337314 | G12: Regression | H12: 1 | I12: 0.16689172 | J12: 0.16689172 | K12: 30.475657 | L12: 1.2707195e-06
A13: 44561 | B13: 166.67 | C13: 4766.18 | D13: =(B13-B12)/B12 -> -0.015185535 | E13: =(C13-C12)/C12 -> 0.043612875 | G13: Residual | H13: 49 | I13: 0.26833528 | J13: 0.0054762303
A14: 44592 | B14: 148.07 | C14: 4515.55 | D14: =(B14-B13)/B13 -> -0.11159777 | E14: =(C14-C13)/C13 -> -0.052585089 | G14: Total | H14: 50 | I14: 0.435227
A15: 44620 | B15: 136.55 | C15: 4373.94 | D15: =(B15-B14)/B14 -> -0.07780104 | E15: =(C15-C14)/C14 -> -0.031360521
A16: 44651 | B16: 134.56 | C16: 4530.41 | D16: =(B16-B15)/B15 -> -0.014573416 | E16: =(C16-C15)/C15 -> 0.035773239 | H16: Coefficients | I16: Standard Error | J16: t Stat | K16: P-value | L16: Lower 95% | M16: Upper 95% | N16: Lower 95.0% | O16: Upper 95.0%
A17: 44681 | B17: 124.7 | C17: 4131.93 | D17: =(B17-B16)/B16 -> -0.073275862 | E17: =(C17-C16)/C16 -> -0.087956719 | G17: Intercept | H17: -0.023654205 | I17: 0.01056302 | J17: -2.2393412 | K17: 0.029705698 | L17: -0.044881388 | M17: -0.0024270223 | N17: -0.044881388 | O17: -0.0024270223
A18: 44712 | B18: 118.85 | C18: 4132.15 | D18: =(B18-B17)/B17 -> -0.04691259 | E18: =(C18-C17)/C17 -> 5.3243884e-05 | G18: X Variable 1 | H18: 1.2545551 | I18: 0.22725487 | J18: 5.5204762 | K18: 1.2707195e-06 | L18: 0.79786934 | M18: 1.7112409 | N18: 0.79786934 | O18: 1.7112409
A19: 44742 | B19: 102.2 | C19: 3785.38 | D19: =(B19-B18)/B18 -> -0.14009255 | E19: =(C19-C18)/C18 -> -0.083919993 | H19: Aumenta la Beta | J19: Aun >2
A20: 44773 | B20: 114.92 | C20: 4130.29 | D20: =(B20-B19)/B19 -> 0.12446184 | E20: =(C20-C19)/C19 -> 0.091116348 | H20: con respecto a
A21: 44804 | B21: 106.45 | C21: 3955 | D21: =(B21-B20)/B20 -> -0.073703446 | E21: =(C21-C20)/C20 -> -0.042440119 | H21: semanal y diaria
A22: 44834 | B22: 83.12 | C22: 3585.62 | D22: =(B22-B21)/B21 -> -0.21916393 | E22: =(C22-C21)/C21 -> -0.093395702 | H22: Sigie siendo B>1, empresa Agresiva
A23: 44865 | B23: 92.68 | C23: 3871.98 | D23: =(B23-B22)/B22 -> 0.11501444 | E23: =(C23-C22)/C22 -> 0.079863455
A24: 44895 | B24: 109.69 | C24: 4080.11 | D24: =(B24-B23)/B23 -> 0.18353474 | E24: =(C24-C23)/C23 -> 0.05375286
A25: 44926 | B25: 117.01 | C25: 3839.5 | D25: =(B25-B24)/B24 -> 0.066733522 | E25: =(C25-C24)/C24 -> -0.058971449
A26: 44957 | B26: 127.33 | C26: 4076.6 | D26: =(B26-B25)/B25 -> 0.08819759 | E26: =(C26-C25)/C25 -> 0.061752832
A27: 44985 | B27: 118.79 | C27: 3970.15 | D27: =(B27-B26)/B26 -> -0.067069819 | E27: =(C27-C26)/C26 -> -0.026112447
A28: 45016 | B28: 122.64 | C28: 4109.31 | D28: =(B28-B27)/B27 -> 0.032410136 | E28: =(C28-C27)/C27 -> 0.035051572
A29: 45046 | B29: 126.72 | C29: 4169.48 | D29: =(B29-B28)/B28 -> 0.033268102 | E29: =(C29-C28)/C28 -> 0.014642361
A30: 45077 | B30: 105.26 | C30: 4179.83 | D30: =(B30-B29)/B29 -> -0.16934975 | E30: =(C30-C29)/C29 -> 0.0024823239
A31: 45107 | B31: 110.37 | C31: 4450.38 | D31: =(B31-B30)/B30 -> 0.048546456 | E31: =(C31-C30)/C30 -> 0.064727513
A32: 45138 | B32: 110.39 | C32: 4588.96 | D32: =(B32-B31)/B31 -> 0.00018120866 | E32: =(C32-C31)/C31 -> 0.031138914
A33: 45169 | B33: 101.71 | C33: 4507.66 | D33: =(B33-B32)/B32 -> -0.078630311 | E33: =(C33-C32)/C32 -> -0.017716432
A34: 45199 | B34: 95.62 | C34: 4288.05 | D34: =(B34-B33)/B33 -> -0.059876118 | E34: =(C34-C33)/C33 -> -0.048719291
... A53: 45777 | B53: 56.4 | C53: 5569.06 | D53: =(B53-B52)/B52 -> -0.11153119 | E53: =(C53-C52)/C52 -> -0.0076249365

Sheet Nike_bond

Sheet WACC
I1: Cálculo del rendimiento esperado de la deuda (debt capital) Hoy (t0) | P1: Costo de deuda en tiempo terminal (anio 5)
B2: Cálculo del rendimiento esperado del capital accionario (equity capital) | I2: https://www.finra.org/finra-data/fixed-income/corp-and-agency | M2: (FINRA para informacion de los Bonos) | P2: (Suponiendo que del 2025 al 2030 NIKE ya no hizo mas emision de deuda)
I3: https://www.sec.gov/ix?doc=/Archives/edgar/data/0000320187/000032018724000044/nke-20240531.htm | M3: o del Balance Sheet (Long Term Debt)
I4: https://markets.businessinsider.com/bonds/finder?borrower=41804&maturity=&yield=&bondtype=&coupon=&currency=&rating=&country=
I5: https://companiesmarketcap.com/nike/total-debt/ | M5: Para Comparar Deuda con otras Empresas Similares
I6: https://www.macrotrends.net/stocks/charts/NKE/nike/long-term-debt | M6: Para Comparar Deuda con otras Empresas Similares
I7: (Resumen de los BONOS emitidos por NIKE) | N7: Promedio Ponderado | R7: Promedio Ponderado
B8: Beta | C8: Estimada | D8: Error | E8: limite Inferior | F8: limite Superior | I8: Vencimiento | J8: Cupón (semianual for NIKE) | K8: Monto (Face Value) | L8: YTM (Buscar por NIKE Luego abrir cada Bono para obtener el YTM) | M8: Weight | N8: WDC | P8: Monto | Q8: YTM | R8: Weight | S8: WDC
B9: Beta Diaria | C9: =daily_prices!H18 -> 1.117937 | D9: =daily_prices!I18 -> 0.052126024 | E9: =C9-D9 -> 1.065811 | F9: =C9+D9 -> 1.170063 | I9: 2026 | J9: 0.02375 | K9: 1000000000 | L9: 0.044696 | M9: =+K9/$K$17 -> 0.14283674 | N9: =L9*M9 -> 0.0063842308 | P9: - | Q9: - | R9: - | S9: -
A10: el mas usado-> | B10: Beta Semanal | C10: =weekly_prices!H18 -> 1.0984573 | D10: =weekly_prices!I18 -> 0.12042526 | E10: =C10-D10 -> 0.978032 | F10: =C10+D10 -> 1.2188825 | I10: 2027 | J10: 0.0275 | K10: 1000000000 | L10: 0.043595 | M10: =+K10/$K$17 -> 0.14283674 | N10: =L10*M10 -> 0.0062269676 | P10: - | Q10: - | R10: - | S10: -
B11: Beta Mensual | C11: =monthly_prices!H18 -> 1.2545551 | D11: =monthly_prices!I18 -> 0.22725487 | E11: =C11-D11 -> 1.0273002 | F11: =C11+D11 -> 1.48181 | I11: 2030 | J11: 0.0285 | K11: 1500000000 | L11: 0.047505 | M11: =+K11/$K$17 -> 0.21425511 | N11: =L11*M11 -> 0.010178189 | P11: - | Q11: - | R11: - | S11: -
I12: 2040 | J12: 0.0325 | K12: 1000000000 | L12: 0.05455 | M12: =+K12/$K$17 -> 0.14283674 | N12: =L12*M12 -> 0.007791744 | P12: =+K12 -> 1000000000 | Q12: =+L12 -> 0.05455 | R12: =+P12/$P$17 -> 0.28563268 | S12: =+Q12*R12 -> 0.015581262
B13: Risk-free= | C13: 0.045497 | D13: 10Y | E13: <- Criterios: Estabilidad (menos suseptible a variaciones del mercado), Horizonte de Valoracion | I13: 2043 | J13: 0.03625 | K13: 500000 | L13: 0.055773 | M13: =+K13/$K$17 -> 7.1418369e-05 | N13: =L13*M13 -> 3.9832167e-06 | P13: =+K13 -> 500000 | Q13: =+L13 -> 0.055773 | R13: =+P13/$P$17 -> 0.00014281634 | S13: =+Q13*R13 -> 7.9652956e-06
B14: E[Rm]= | C14: =weekly_prices!H33 -> 0.12868515 | D14: anual | E14: <- Dos opciones: Mercado de Futuros o Estimar el precio de Mercado con Informacion Historica (ver "weekly" tab). Nos quedamos con el 12.87% por que CAPM mide el riesgo de mercado de la empresa con respecto al Mercado. No usamos el de los Futuros de -4% de momento. | I14: 2045 | J14: 3.875 | K14: 1000000000 | L14: 0.055824 | M14: =+K14/$K$17 -> 0.14283674 | N14: =L14*M14 -> 0.007973718 | P14: =+K14 -> 1000000000 | Q14: =+L14 -> 0.055824 | R14: =+P14/$P$17 -> 0.28563268 | S14: =+Q14*R14 -> 0.015945159
B15: Premio mkt= | C15: =C14-C13 -> 0.083188154 | I15: 2046 | J15: 0.03375 | K15: 500000 | L15: 0.055409 | M15: =+K15/$K$17 -> 7.1418369e-05 | N15: =L15*M15 -> 3.9572204e-06 | P15: =+K15 -> 500000 | Q15: =+L15 -> 0.055409 | R15: =+P15/$P$17 -> 0.00014281634 | S15: =+Q15*R15 -> 7.9133105e-06
B16: CAPM: | C16: (5 anios) | E16: (6+ anios, perpetuidad) | I16: 2050 | J16: 0.03375 | K16: 1500000000 | L16: 0.055562 | M16: =+K16/$K$17 -> 0.21425511 | N16: =L16*M16 -> 0.011904442 | P16: =+K16 -> 1500000000 | Q16: =+L16 -> 0.055562 | R16: =+P16/$P$17 -> 0.42844901 | S16: =+Q16*R16 -> 0.023805484
A17: Rendimiento esperado de NIKE o "Costo" de Equity: | B17: E[RNIKE]= Rf + B(Rm-Rf) = Ce | C17: =C13+(C10*C15) -> 0.13687563 | E17: =C13+(1*C15) -> 0.12868515 | F17: Beta = 1 porque en perpetuidad el Stock madura y se mueve junto con el Mercado | K17: =+SUM(K9:K16) -> 7001000000 | M17: =+SUM(M9:M16) -> 1 | N17: =+SUM(N9:N16) -> 0.050467232 | P17: =+SUM(P12:P16) -> 3501000000 | S17: =+SUM(S12:S16) -> 0.055347784
N18: Yield Ponderado de todas las Emisiones de Bonos de Nike | Q18: Suponiendo que los YTM se mantienen | S18: Si en 2026 le presto a Nike y me quedo perpetuamente, este es el Rendimiento Esperado
B19: Estructura de Capital (0) | K19: =7000/11983 -> 0.58416089 | N19: o tambien conocido como
C20: (son valores de Mercado abajo) | N20: Rendimiento esperado promedio ponderado si un Inversionista invierte en Bonos de NIKE | S20: Rendimiento esperado promedio ponderado si un Inversionista invierte en Bonos de NIKE
B21: Deuda Total = | C21: ='[1]Capital Structure Summary'!$N$18 -> 11983 | D21: mdd | E21: D/V= | F21: =C21/$C$23 -> 0.45367811 | G21: (D/D+E) | I21: Cd(0)= | J21: =+N17 -> 0.050467232 | K21: Costo de la Deduda t0 (hoy)
B22: Equity Común Total = | C22: ='[1]Capital Structure Summary'!$N$19 -> 14430 | D22: mdd | E22: E/V= | F22: =C22/$C$23 -> 0.54632189 | G22: (E/D+E) | I22: Cd(6)= | J22: =+S17 -> 0.055347784
B23: Suma Capital (V)= | C23: =SUM(C21:C22) -> 26413 | E23: Tax= | F23: ='[1]Income Statement'!$H$85 -> 0.149253
E26: WACC(0)= | F26: =J21*F21*(1-F23) + C17*F22 -> 0.094256753 | G26: From "Nike_bond" | I26: Taxes:
B27: Estructura de Capital (6) | I27: UaImp | J27: 4623 | K27: 4886 | L27: 4325 | M27: 4801
B28: Deuda total = | E28: D/V= | F28: 0.45 | G28: Suponemos que la estructura de capital no cambia drasticamente a partir del anio 6 en adelante | I28: Impuestos | J28: 863 | K28: 646 | L28: 2392 | M28: 772
B29: Equity Común = | E29: E/V= | F29: 0.55 | I29: Tax% | J29: =J28/J27 -> 0.18667532 | K29: =K28/K27 -> 0.13221449 | L29: =L28/L27 -> 0.55306358 | M29: =M28/M27 -> 0.16079983
B30: V = | E30: Tax= | F30: =F23 -> 0.149253
E32: WACC(6)= | F32: =J22*F28*(1-F30) +E17*F29 -> 0.091965967
F35: Fp: Flujos de Efectivo en Perpetuidad
F36: VT: Valor Terminal (anio 6 o fin del anio 5)
F37: 5 anios porque es el Horizonte de tiempo determinado segun programas o planes de Inversion de la Empresa

Sheet FCFF
C1: Cash Flows
C2: Actual (t0) | D2: 1 | E2: 2 | F2: 3 | G2: 4 | H2: 5 | L2: 6 en adelante | M2: Para calcular la Perpetuidad, el Valor Perpetuo de la empresa)
A3: Dinero disponible para Invertir en Activo Fijo o Capital de Trabajo | B3: EBIT(1-tax)= NOPAT (Net Operating Profit After Tax) | C3: ='[1]Income Statement'!$H$33*(1-WACC!F23) -> 5745.9452 | D3: =C3*(1+$C$21) -> 5826.871 | E3: =D3*(1+$C$21) -> 5908.9365 | F3: =E3*(1+$C$21) -> 5992.1578 | G3: =F3*(1+$C$21) -> 6076.5512 | H3: =G3*(1+$C$21) -> 6162.1332 | L3: =H3*(1+K21) -> 6306.9433
A4: Activo Fijo | B4: Capex = | C4: =ABS('[1]Cash Flow'!$K$31) -> 864
B5: Depreciación = | C5: ='[1]Cash Flow'!$K$19 -> 93 | O5: Administracion del capital de Trabajo (NETO)
B6: Capex Neto = | C6: =C4-C5 -> 771 | O6: CTN=AC-PC | P6: (Capital de Trabajo Neto) | R6: Forma part del presupuesto global de la empresa (inversiones a futuro)
A7: Administracion del Capital de Trabajo Neto Operativo (CTNO), compromisos a Corto Plazo | B7: Change in Acc. Receivable | C7: ='[1]Cash Flow'!$K$25 -> -818 | O7: dCTN=dAC=dPC | P7: (deltas)
B8: Change In Inventories | C8: ='[1]Cash Flow'!$K$26 -> 1041 | O8: Capital de trabajo (Operatvo) = Activo Circuilante Operativo - Pasivo Circulante Operativo
B9: Change in Acc. Payable | C9: ='[1]Cash Flow'!$K$27 -> 622
B10: Cambio en Capital de Trabajo = | C10: =(C7+C8)-C9 -> -399 | O10: ACO: | Q10: ejemplo: | R10: PCO: | S10: ejemplo:
B11: Tasa de Reinversión (RR) = | C11: =(C6+C10)/C3 -> 0.064741306 | J11: Tasa reinversión= | K11: =K21/K20 -> 0.25552931 | O11: CxC (cuentas por cobrar) Clientes | Q11: 800000 | R11: CxP (Cuentas por Pagar) Proveedores | S11: 200000
B12: Reinversión = | D12: =$C$11*D3 -> 377.23924 | E12: =$C$11*E3 -> 382.55227 | F12: =$C$11*F3 -> 387.94012 | G12: =$C$11*G3 -> 393.40386 | H12: =$C$11*H3 -> 398.94455 | L12: =L3*K11 -> 1611.6089 | O12: Inventatrios | Q12: -100000
B13: FCFF = | C13: =C3-C6-C10 -> 5373.9452 | D13: =D3-D12 -> 5449.6317 | E13: =E3-E12 -> 5526.3842 | F13: =F3-F12 -> 5604.2177 | G13: =G3-G12 -> 5683.1473 | H13: =H3-H12 -> 5763.1886 | L13: =L3-L12 -> 4695.3344 | O13: Cambio ACO = | Q13: =Q11+Q12 -> 700000 | R13: Cambio PCO = | S13: =S11+S12 -> 200000
Q14: faltantes | S14: excedente
B15: ROC (Return on Capital): | J15: ROC:
B16: Debt capital | C16: =WACC!C21 -> 11983 | O16: En el flujo de efectivo se reflejan los | R16: Cambio CTNO (Capital de Trabajo Neto Operativo) = | S16: =Q13-S13 -> 500000 | T16: Necesidad o Faltante
B17: Equity capital | C17: =WACC!C22 -> 14430 | O17: cambios en ACO y PCO
B18: Total capital = | C18: =SUM(C16:C17) -> 26413 | R18: Utilidades, Prestamos, creditos, etc.. Para conseguir ese dinero | S18: Signo Positivo es un Faltante
B19: NOPAT (Utilidad Operativa Neta despues de Tax) = | C19: =C3 -> 5745.9452 | S19: Signo Negativo es un Excedente
B20: ROC = | C20: =C19/C18 -> 0.21754232 | J20: WACC(6)= | K20: =WACC!F32 -> 0.091965967
B21: Tasa de Crecimiento (RR x ROC)= | C21: =C11*C20 -> 0.014083974 | J21: g=risk_free = | K21: 0.0235 | L21: <-Con base en un estimado de
L22: la politica monetaria dentro de 5 anios
G23: Valor Terminal (5)= | H23: =L13/(K20-K21) -> 68579.1 | I23: <- valor perpetuo posicionado en el anio 6 | O23: Salud Financiera de la Empresa:
B24: WACC(0) = | C24: =WACC!F26 -> 0.094256753 | O24: Rentabilidad (R): Margenes de Utilidad (Que tan bueno soy para generar utilidad a partir de las ventas)
B25: Valor present de FCFF: | D25: =D13/(1+$C$24)^D2 -> 4980.213 | E25: =E13/(1+$C$24)^E2 -> 4615.3284 | F25: =F13/(1+$C$24)^F2 -> 4277.1776 | G25: =G13/(1+$C$24)^G2 -> 3963.8022 | H25: =H13/(1+$C$24)^H2 -> 3673.3868 | O25: Liquidez: Razon Circulante (Capacida de cumplir compromisos de corto plazo)
B26: WACC(6)= | C26: =WACC!F32 -> 0.091965967 | H26: =H23/(1+C26)^H2 -> 44171.919 | I26: <- Valor Presente del Valor Perpetuo posicionado en el anio 5, Conocido como Valor Terminal de la Empresa | O26: Solvencia: Cobertura de Intereses, Endeudamiento (Capacida de cumplir compromisos de largo plazo)
D27: =D25+D26 -> 4980.213 | E27: =E25+E26 -> 4615.3284 | F27: =F25+F26 -> 4277.1776 | G27: =G25+G26 -> 3963.8022 | H27: =H25+H26 -> 47845.306
B28: Suma VP FCFF= | C28: =SUM(D27:H27) -> 65681.827 | D28: <- Conocido como el Valor de los Activos Operacionales | O28: ROE: Utilidad Neta / Capital Contable(Equity) - que tan bueno es el peso invertido como socio de la empresa para conertirse en Utilidad
O29: ROC: Inncluye las dos fuentes de capitalizacion Deuda y Acciones
B30: Valor del Equity (FCFE):
B31: Valor de los Activos Operacionales= | C31: =C28 -> 65681.827 | O31: Eficiencia: Que tan bueno eres para convertir Activo Fijo en Utilidad
B32: + efectivo y valores de mercado= | C32: ='[1]Balance Sheet'!$K$19 -> 11582 | D32: <- Del Balance Sheet $K19, traer Activos Circulantes, que se hacen rapido en Efectivo en el Mercado | O32: ROI or ROIC: Utilidad / Inversion(Activo fijo)
B33: - deuda y activos no operacionales= | C33: =-C16 -> -11983 | D33: <- Deuda a Valor de Mercado "en este momento" (Face Value de $7milMillomes usd). Este es el Valor si HOY retirara esa deuda, la pagaria a Valor de Mercado | O33: Para obtener el ROI de los Estados Financieros: ROI = Net Income/Non current Assets(Activo fijo)
B34: - accionistas minoritarios= | C34: 0
B35: Valor del Equity en capital accionario= | C35: =SUM(C31:C34) -> 65280.827
B36: Outstanding Shares= | C36: ='[1]Key Stats'!$B$47 -> 1475.9905
B37: Valor del equity por acción= | C37: =C35/C36 -> 44.228488 | D37: Valor de Referencia o Valor Intrinseco de la Empresa (sin considerar el sentimiento del Merado) Comparar con el de la hoja Nike_bond
B38: Precio de mercado= | C38: =monthly_prices!B49 -> 75.67 | D38: <----------------- | E38: ---------------- | F38: Precio de Mercado Dic-2024: $75.67
B39: Sobrevaloración (o Subvaloracion si es < 0)= | C39: =(C38/C37)-1 -> 0.71088826 | D39: Sobrevalorada | E39: Se puede ver que ya lleva tiempo sobrevalorada La tendencia del precio va a la baja
B40: Prices-to-earnings ratio:
...
