Workbook

Sheet precios
A1: AAPL | B1: NVDA | C1: NFLX | D1: AMZN | E1: COST | F1: JNJ | G1: BAC | H1: PG | I1: KO | J1: GE | K1: DE | L1: CVX | M1: PLD | N1: APD | O1: GOVT | P1: TLT | Q1: IBTA.L | R1: IEF | S1: IEI | T1: SHY
A2: 72.716064 | B2: 5.9721613 | C2: 329.81 | D2: 94.900497 | E2: 267.59244 | F2: 126.05515 | G2: 31.275545 | H2: 108.41987 | I2: 46.749748 | J2: 58.053135 | K2: 164.54092 | L2: 96.158691 | M2: 76.861359 | N2: 203.90211 | O2: 23.16083 | P2: 119.34701 | Q2: 5.2519999 | R2: 99.02787 | S2: 114.47618 | T2: 76.313362
A3: 72.009132 | B3: 5.8765712 | C3: 325.89999 | D3: 93.748497 | E3: 267.81284 | F3: 124.59575 | G3: 30.626158 | H3: 107.69069 | I3: 46.494701 | J3: 58.247795 | K3: 163.32216 | L3: 95.826096 | M3: 77.722137 | N3: 199.36786 | O3: 23.276674 | P3: 121.18495 | Q3: 5.256 | R3: 99.68969 | S3: 114.83968 | T3: 76.376457
A4: 72.582916 | B4: 5.9012156 | C4: 335.82999 | D4: 95.143997 | E4: 267.88623 | F4: 124.44032 | G4: 30.582277 | H4: 107.84004 | I4: 46.477699 | J4: 59.075035 | K4: 164.49442 | L4: 95.501427 | M4: 77.417801 | N4: 199.27962 | O4: 23.249956 | P4: 120.49681 | Q4: 5.2529998 | R4: 99.582367 | S4: 114.77606 | T4: 76.349388
A5: 72.24157 | B5: 5.9726601 | C5: 330.75 | D5: 95.343002 | E5: 267.46399 | F5: 125.20022 | G5: 30.380442 | H5: 107.17235 | I5: 46.12064 | J5: 58.637089 | K5: 161.63831 | L5: 94.281921 | M5: 76.922218 | N5: 200.12651 | O5: 23.205402 | P5: 119.90443 | Q5: 5.2579999 | R5: 99.439247 | S5: 114.73064 | T5: 76.349388
A6: 73.403633 | B6: 5.9838614 | C6: 339.26001 | D6: 94.598503 | E6: 270.53018 | F6: 125.18294 | G6: 30.687592 | H6: 107.6292 | I6: 46.205643 | J6: 58.10181 | K6: 163.6478 | L6: 93.204964 | M6: 77.339569 | N6: 201.21153 | O6: 23.169746 | P6: 119.11182 | Q6: 5.2544999 | R6: 99.206741 | S6: 114.57616 | T6: 76.313362
A7: 74.962807 | B7: 6.0495796 | C7: 335.66 | D7: 95.052498 | E7: 274.87234 | F7: 125.55428 | G7: 30.74024 | H7: 108.80643 | I7: 47.047298 | J7: 57.955822 | K7: 165.22937 | L7: 93.054504 | M7: 77.348259 | N7: 205.98401 | O7: 23.187574 | P7: 119.52985 | Q7: 5.2540002 | R7: 99.278267 | S7: 114.57616 | T7: 76.322342
A8: 75.132271 | B8: 6.0819411 | C8: 329.04999 | D8: 94.157997 | E8: 272.87103 | F8: 125.26932 | G8: 30.485758 | H8: 108.91186 | I8: 47.20882 | J8: 56.787945 | K8: 161.34985 | L8: 92.207191 | M8: 77.765602 | N8: 204.66081 | O8: 23.241037 | P8: 120.59264 | Q8: 5.2490001 | R8: 99.49295 | S8: 114.68521 | T8: 76.340378
A9: 76.737404 | B9: 6.2726245 | C9: 338.92001 | D9: 94.565002 | E9: 275.28537 | F9: 125.82205 | G9: 30.766573 | H9: 109.71133 | I9: 47.718922 | J9: 58.977711 | K9: 162.5686 | L9: 92.381401 | M9: 79.817581 | N9: 208.94814 | O9: 23.214304 | P9: 120.22678 | Q9: 5.256 | R9: 99.376671 | S9: 114.62156 | T9: 76.33136
A10: 75.701202 | B10: 6.1556253 | C10: 338.69 | D10: 93.472 | E10: 275.17529 | F10: 126.53017 | G10: 30.994732 | H10: 109.54442 | I10: 47.608395 | J10: 58.539761 | K10: 161.57309 | L10: 92.096352 | M10: 78.800285 | N10: 206.88382 | O10: 23.258856 | P10: 120.84525 | Q10: 5.2554998 | R10: 99.573441 | S10: 114.73973 | T10: 76.340378
A11: 75.376793 | B11: 6.1130571 | C11: 339.07001 | D11: 93.100998 | E11: 276.1575 | F11: 126.95324 | G11: 30.424328 | H11: 110.66015 | I11: 48.203503 | J11: 57.761181 | K11: 160.87538 | L11: 91.961693 | M11: 80.174057 | N11: 207.71309 | O11: 23.294491 | P11: 121.64665 | Q11: 5.257 | R11: 99.823814 | S11: 114.86697 | T11: 76.376457
A12: 76.320992 | B12: 6.1966987 | C12: 338.62 | D12: 93.897003 | E12: 278.18643 | F12: 127.9809 | G12: 30.468204 | H12: 110.75677 | I12: 48.305519 | J12: 57.615189 | K12: 163.24771 | L12: 92.563538 | M12: 81.165253 | N12: 207.98656 | O12: 23.258856 | P12: 121.26336 | Q12: 5.256 | R12: 99.618141 | S12: 114.78514 | T12: 76.376457
A13: 77.165947 | B13: 6.2054119 | C13: 339.67001 | D13: 93.236 | E13: 279.70114 | F13: 128.8186 | G13: 30.459435 | H13: 111.05548 | I13: 48.407532 | J13: 57.469208 | K13: 163.92688 | L13: 91.526161 | M13: 81.965157 | N13: 209.07161 | O13: 23.232121 | P13: 120.22678 | Q13: 5.2589998 | R13: 99.537651 | S13: 114.76702 | T13: 76.40345
... A1288: 251.92302 | B1288: 137.47736 | C1288: 900.42999 | D1288: 221.3 | E1288: 921.1922 | F1288: 142.20172 | G1288: 43.634636 | H1288: 166.0773 | I1288: 61.5756 | J1288: 167.78783 | K1288: 421.54724 | L1288: 141.50053 | M1288: 104.17242 | N1288: 285.18674 | O1288: 22.284819 | P1288: 86.901031 | Q1288: 5.6149998 | R1288: 91.765472 | S1288: 114.58266 | T1288: 81.132614

Sheet rets
B1: CAMBIOS PORCENTUALES | V1: EXCESOS | AR1: ESTADÍSTICOS DESCRIPTIVOS
A2: obs | B2: AAPL | C2: NVDA | D2: NFLX | E2: AMZN | F2: COST | G2: JNJ | H2: BAC | I2: PG | J2: KO | K2: GE | L2: DE | M2: CVX | N2: PLD | O2: APD | P2: GOVT | Q2: TLT | R2: IBTA.L | S2: IEF | T2: IEI | U2: SHY | V2: AAPL | W2: NVDA | X2: NFLX | Y2: AMZN | Z2: COST | AA2: JNJ | AB2: BAC | AC2: PG | AD2: KO | AE2: GE | AF2: DE | AG2: CVX | AH2: PLD | AI2: APD | AJ2: GOVT | AK2: TLT | AL2: IBTA.L | AM2: IEF | AN2: IEI | AO2: SHY | AR2: AAPL | AS2: NVDA | AT2: NFLX | AU2: AMZN | AV2: COST | AW2: JNJ | AX2: BAC | AY2: PG | AZ2: KO | BA2: GE | BB2: DE | BC2: CVX | BD2: PLD | BE2: APD | BF2: GOVT | BG2: TLT | BH2: IBTA.L | BI2: IEF | BJ2: IEI | BK2: SHY
A3: 1 | B3: =(precios!A3-precios!A2)/precios!A2 -> -0.0097218142 | C3: =(precios!B3-precios!B2)/precios!B2 -> -0.01600595 | D3: =(precios!C3-precios!C2)/precios!C2 -> -0.011855322 | E3: =(precios!D3-precios!D2)/precios!D2 -> -0.012139035 | F3: =(precios!E3-precios!E2)/precios!E2 -> 0.00082363295 | G3: =(precios!F3-precios!F2)/precios!F2 -> -0.011577444 | H3: =(precios!G3-precios!G2)/precios!G2 -> -0.020763423 | I3: =(precios!H3-precios!H2)/precios!H2 -> -0.0067255144 | ... U3: =(precios!T3-precios!T2)/precios!T2 -> 0.00082678958 | V3: =B3-AR$3 -> -0.010880631 | W3: =C3-AS$3 -> -0.019000779 | X3: =D3-AT$3 -> -0.013052801 | Y3: =E3-AU$3 -> -0.013046237 | Z3: =F3-AV$3 -> -0.00025023654 | AA3: =G3-AW$3 -> -0.011745455 | AB3: =H3-AX$3 -> -0.021267622 | AC3: =I3-AY$3 -> -0.0071416534 | ... AO3: =U3-BK$3 -> 0.00077846358 | AQ3: Media= | AR3: =AVERAGE(B3:B1288) -> 0.0011588167 | AS3: =AVERAGE(C3:C1288) -> 0.0029948295 | AT3: =AVERAGE(D3:D1288) -> 0.0011974796 | AU3: =AVERAGE(E3:E1288) -> 0.00090720243 | AV3: =AVERAGE(F3:F1288) -> 0.0010738695 | AW3: =AVERAGE(G3:G1288) -> 0.00016801113 | AX3: =AVERAGE(H3:H1288) -> 0.00050419936 | AY3: =AVERAGE(I3:I1288) -> 0.00041613901 | ... BK3: =AVERAGE(U3:U1288) -> 4.8326007e-05
A4: 2 | B4: =(precios!A4-precios!A3)/precios!A3 -> 0.0079682098 | C4: =(precios!B4-precios!B3)/precios!B3 -> 0.0041936657 | D4: =(precios!C4-precios!C3)/precios!C3 -> 0.030469447 | E4: =(precios!D4-precios!D3)/precios!D3 -> 0.014885574 | F4: =(precios!E4-precios!E3)/precios!E3 -> 0.00027405249 | G4: =(precios!F4-precios!F3)/precios!F3 -> -0.0012475037 | H4: =(precios!G4-precios!G3)/precios!G3 -> -0.0014327773 | I4: =(precios!H4-precios!H3)/precios!H3 -> 0.0013868704 | ... U4: =(precios!T4-precios!T3)/precios!T3 -> -0.0003544167 | V4: =B4-AR$3 -> 0.0068093931 | W4: =C4-AS$3 -> 0.0011988362 | X4: =D4-AT$3 -> 0.029271968 | Y4: =E4-AU$3 -> 0.013978372 | Z4: =F4-AV$3 -> -0.000799817 | AA4: =G4-AW$3 -> -0.0014155148 | AB4: =H4-AX$3 -> -0.0019369766 | AC4: =I4-AY$3 -> 0.00097073138 | ... AO4: =U4-BK$3 -> -0.0004027427 | AQ4: Var=
A5: 3 | B5: =(precios!A5-precios!A4)/precios!A4 -> -0.0047028524 | C5: =(precios!B5-precios!B4)/precios!B4 -> 0.012106745 | D5: =(precios!C5-precios!C4)/precios!C4 -> -0.015126662 | E5: =(precios!D5-precios!D4)/precios!D4 -> 0.0020916204 | F5: =(precios!E5-precios!E4)/precios!E4 -> -0.001576196 | G5: =(precios!F5-precios!F4)/precios!F4 -> 0.0061065656 | H5: =(precios!G5-precios!G4)/precios!G4 -> -0.0065997581 | I5: =(precios!H5-precios!H4)/precios!H4 -> -0.0061915229 | ... U5: =(precios!T5-precios!T4)/precios!T4 -> 0 | V5: =B5-AR$3 -> -0.0058616691 | W5: =C5-AS$3 -> 0.0091119155 | X5: =D5-AT$3 -> -0.016324141 | Y5: =E5-AU$3 -> 0.001184418 | Z5: =F5-AV$3 -> -0.0026500655 | AA5: =G5-AW$3 -> 0.0059385545 | AB5: =H5-AX$3 -> -0.0071039575 | AC5: =I5-AY$3 -> -0.0066076619 | ... AO5: =U5-BK$3 -> -4.8326007e-05 | AQ5: Desvest=
A6: 4 | B6: =(precios!A6-precios!A5)/precios!A5 -> 0.016085802 | C6: =(precios!B6-precios!B5)/precios!B5 -> 0.0018754427 | D6: =(precios!C6-precios!C5)/precios!C5 -> 0.025729432 | E6: =(precios!D6-precios!D5)/precios!D5 -> -0.0078086403 | F6: =(precios!E6-precios!E5)/precios!E5 -> 0.011463946 | G6: =(precios!F6-precios!F5)/precios!F5 -> -0.00013802355 | H6: =(precios!G6-precios!G5)/precios!G5 -> 0.010110119 | I6: =(precios!H6-precios!H5)/precios!H5 -> 0.0042628139 | ... U6: =(precios!T6-precios!T5)/precios!T5 -> -0.0004718571 | V6: =B6-AR$3 -> 0.014926986 | W6: =C6-AS$3 -> -0.0011193868 | X6: =D6-AT$3 -> 0.024531953 | Y6: =E6-AU$3 -> -0.0087158427 | Z6: =F6-AV$3 -> 0.010390076 | AA6: =G6-AW$3 -> -0.00030603468 | AB6: =H6-AX$3 -> 0.0096059199 | AC6: =I6-AY$3 -> 0.0038466749 | ... AO6: =U6-BK$3 -> -0.00052018311
A7: 5 | B7: =(precios!A7-precios!A6)/precios!A6 -> 0.021241096 | C7: =(precios!B7-precios!B6)/precios!B6 -> 0.010982569 | D7: =(precios!C7-precios!C6)/precios!C6 -> -0.010611348 | E7: =(precios!D7-precios!D6)/precios!D6 -> 0.0047991748 | F7: =(precios!E7-precios!E6)/precios!E6 -> 0.016050568 | G7: =(precios!F7-precios!F6)/precios!F6 -> 0.0029664228 | H7: =(precios!G7-precios!G6)/precios!G6 -> 0.0017156297 | I7: =(precios!H7-precios!H6)/precios!H6 -> 0.010937838 | ... U7: =(precios!T7-precios!T6)/precios!T6 -> 0.00011767005 | V7: =B7-AR$3 -> 0.020082279 | W7: =C7-AS$3 -> 0.00798774 | X7: =D7-AT$3 -> -0.011808828 | Y7: =E7-AU$3 -> 0.0038919724 | Z7: =F7-AV$3 -> 0.014976699 | AA7: =G7-AW$3 -> 0.0027984117 | AB7: =H7-AX$3 -> 0.0012114304 | AC7: =I7-AY$3 -> 0.010521699 | ... AO7: =U7-BK$3 -> 6.9344046e-05 | AQ7: MATRIZ CORRELACIONES
A8: 6 | B8: =(precios!A8-precios!A7)/precios!A7 -> 0.0022606426 | C8: =(precios!B8-precios!B7)/precios!B7 -> 0.0053493812 | D8: =(precios!C8-precios!C7)/precios!C7 -> -0.019692593 | E8: =(precios!D8-precios!D7)/precios!D7 -> -0.0094105968 | F8: =(precios!E8-precios!E7)/precios!E7 -> -0.0072808789 | G8: =(precios!F8-precios!F7)/precios!F7 -> -0.0022696598 | H8: =(precios!G8-precios!G7)/precios!G7 -> -0.0082784737 | I8: =(precios!H8-precios!H7)/precios!H7 -> 0.00096890385 | ... U8: =(precios!T8-precios!T7)/precios!T7 -> 0.00023631204 | V8: =B8-AR$3 -> 0.0011018259 | W8: =C8-AS$3 -> 0.0023545517 | X8: =D8-AT$3 -> -0.020890073 | Y8: =E8-AU$3 -> -0.010317799 | Z8: =F8-AV$3 -> -0.0083547484 | AA8: =G8-AW$3 -> -0.002437671 | AB8: =H8-AX$3 -> -0.0087826731 | AC8: =I8-AY$3 -> 0.00055276485 | ... AO8: =U8-BK$3 -> 0.00018798604
A9: 7 | B9: =(precios!A9-precios!A8)/precios!A8 -> 0.021364096 | C9: =(precios!B9-precios!B8)/precios!B8 -> 0.031352386 | D9: =(precios!C9-precios!C8)/precios!C8 -> 0.02999552 | E9: =(precios!D9-precios!D8)/precios!D8 -> 0.0043225782 | F9: =(precios!E9-precios!E8)/precios!E8 -> 0.0088479057 | G9: =(precios!F9-precios!F8)/precios!F8 -> 0.0044123684 | H9: =(precios!G9-precios!G8)/precios!G8 -> 0.0092113546 | I9: =(precios!H9-precios!H8)/precios!H8 -> 0.0073405138 | ... U9: =(precios!T9-precios!T8)/precios!T8 -> -0.00011812811 | V9: =B9-AR$3 -> 0.020205279 | W9: =C9-AS$3 -> 0.028357556 | X9: =D9-AT$3 -> 0.028798041 | Y9: =E9-AU$3 -> 0.0034153758 | Z9: =F9-AV$3 -> 0.0077740362 | AA9: =G9-AW$3 -> 0.0042443572 | AB9: =H9-AX$3 -> 0.0087071552 | AC9: =I9-AY$3 -> 0.0069243748 | ... AO9: =U9-BK$3 -> -0.00016645411
A10: 8 | B10: =(precios!A10-precios!A9)/precios!A9 -> -0.013503213 | C10: =(precios!B10-precios!B9)/precios!B9 -> -0.018652344 | D10: =(precios!C10-precios!C9)/precios!C9 -> -0.00067865861 | E10: =(precios!D10-precios!D9)/precios!D9 -> -0.011558212 | F10: =(precios!E10-precios!E9)/precios!E9 -> -0.00039986471 | G10: =(precios!F10-precios!F9)/precios!F9 -> 0.0056279662 | H10: =(precios!G10-precios!G9)/precios!G9 -> 0.0074158065 | I10: =(precios!H10-precios!H9)/precios!H9 -> -0.0015213403 | ... U10: =(precios!T10-precios!T9)/precios!T9 -> 0.00011814206 | V10: =B10-AR$3 -> -0.014662029 | W10: =C10-AS$3 -> -0.021647173 | X10: =D10-AT$3 -> -0.0018761382 | Y10: =E10-AU$3 -> -0.012465414 | Z10: =F10-AV$3 -> -0.0014737342 | AA10: =G10-AW$3 -> 0.0054599551 | AB10: =H10-AX$3 -> 0.0069116071 | AC10: =I10-AY$3 -> -0.0019374793 | ... AO10: =U10-BK$3 -> 6.9816057e-05
A11: 9 | B11: =(precios!A11-precios!A10)/precios!A10 -> -0.0042853941 | C11: =(precios!B11-precios!B10)/precios!B10 -> -0.0069153343 | D11: =(precios!C11-precios!C10)/precios!C10 -> 0.0011219844 | E11: =(precios!D11-precios!D10)/precios!D10 -> -0.0039691265 | F11: =(precios!E11-precios!E10)/precios!E10 -> 0.0035693911 | G11: =(precios!F11-precios!F10)/precios!F10 -> 0.0033435913 | H11: =(precios!G11-precios!G10)/precios!G10 -> -0.018403258 | I11: =(precios!H11-precios!H10)/precios!H10 -> 0.010185186 | ... U11: =(precios!T11-precios!T10)/precios!T10 -> 0.00047261237 | V11: =B11-AR$3 -> -0.0054442108 | W11: =C11-AS$3 -> -0.0099101637 | X11: =D11-AT$3 -> -7.5495282e-05 | Y11: =E11-AU$3 -> -0.004876329 | Z11: =F11-AV$3 -> 0.0024955216 | AA11: =G11-AW$3 -> 0.0031755801 | AB11: =H11-AX$3 -> -0.018907458 | AC11: =I11-AY$3 -> 0.0097690471 | ... AO11: =U11-BK$3 -> 0.00042428636
A12: 10 | B12: =(precios!A12-precios!A11)/precios!A11 -> 0.012526383 | C12: =(precios!B12-precios!B11)/precios!B11 -> 0.013682439 | D12: =(precios!C12-precios!C11)/precios!C11 -> -0.0013271956 | E12: =(precios!D12-precios!D11)/precios!D11 -> 0.008549911 | F12: =(precios!E12-precios!E11)/precios!E11 -> 0.0073470054 | G12: =(precios!F12-precios!F11)/precios!F11 -> 0.0080948244 | H12: =(precios!G12-precios!G11)/precios!G11 -> 0.0014421567 | I12: =(precios!H12-precios!H11)/precios!H11 -> 0.00087311154 | ... U12: =(precios!T12-precios!T11)/precios!T11 -> 0 | V12: =B12-AR$3 -> 0.011367567 | W12: =C12-AS$3 -> 0.010687609 | X12: =D12-AT$3 -> -0.0025246752 | Y12: =E12-AU$3 -> 0.0076427086 | Z12: =F12-AV$3 -> 0.0062731359 | AA12: =G12-AW$3 -> 0.0079268133 | AB12: =H12-AX$3 -> 0.00093795733 | AC12: =I12-AY$3 -> 0.00045697253 | ... AO12: =U12-BK$3 -> -4.8326007e-05
A13: 11 | B13: =(precios!A13-precios!A12)/precios!A12 -> 0.011071075 | C13: =(precios!B13-precios!B12)/precios!B12 -> 0.0014061109 | D13: =(precios!C13-precios!C12)/precios!C12 -> 0.0031008751 | E13: =(precios!D13-precios!D12)/precios!D12 -> -0.0070396614 | F13: =(precios!E13-precios!E12)/precios!E12 -> 0.0054449437 | G13: =(precios!F13-precios!F12)/precios!F12 -> 0.0065455069 | H13: =(precios!G13-precios!G12)/precios!G12 -> -0.00028784069 | I13: =(precios!H13-precios!H12)/precios!H12 -> 0.0026970242 | ... U13: =(precios!T13-precios!T12)/precios!T12 -> 0.00035341778 | V13: =B13-AR$3 -> 0.0099122586 | W13: =C13-AS$3 -> -0.0015887186 | X13: =D13-AT$3 -> 0.0019033955 | Y13: =E13-AU$3 -> -0.0079468639 | Z13: =F13-AV$3 -> 0.0043710743 | AA13: =G13-AW$3 -> 0.0063774958 | AB13: =H13-AX$3 -> -0.00079204005 | AC13: =I13-AY$3 -> 0.0022808852 | ... AO13: =U13-BK$3 -> 0.00030509177
A14: 12 | B14: =(precios!A14-precios!A13)/precios!A13 -> -0.0021573624 | C14: =(precios!B14-precios!B13)/precios!B13 -> -0.0047089448 | D14: =(precios!C14-precios!C13)/precios!C13 -> 0.011608758 | E14: =(precios!D14-precios!D13)/precios!D13 -> 0.005617794 | F14: =(precios!E14-precios!E13)/precios!E13 -> 0.016446403 | G14: =(precios!F14-precios!F13)/precios!F13 -> 0.0032871222 | H14: =(precios!G14-precios!G13)/precios!G13 -> -0.0079814414 | I14: =(precios!H14-precios!H13)/precios!H13 -> -0.0012038755 | ... U14: =(precios!T14-precios!T13)/precios!T13 -> 0.00017760596 | V14: =B14-AR$3 -> -0.0033161791 | W14: =C14-AS$3 -> -0.0077037743 | X14: =D14-AT$3 -> 0.010411279 | Y14: =E14-AU$3 -> 0.0047105916 | Z14: =F14-AV$3 -> 0.015372533 | AA14: =G14-AW$3 -> 0.0031191111 | AB14: =H14-AX$3 -> -0.0084856408 | AC14: =I14-AY$3 -> -0.0016200145 | ... AO14: =U14-BK$3 -> 0.00012927995
A15: 13 | B15: =(precios!A15-precios!A14)/precios!A14 -> -0.0046295682 | C15: =(precios!B15-precios!B14)/precios!B14 -> -0.00066946938 | D15: =(precios!C15-precios!C14)/precios!C14 -> -0.016015612 | E15: =(precios!D15-precios!D14)/precios!D14 -> 0.008961388 | F15: =(precios!E15-precios!E14)/precios!E14 -> 0.011524888 | G15: =(precios!F15-precios!F14)/precios!F14 -> -0.0026085844 | H15: =(precios!G15-precios!G14)/precios!G14 -> -0.0050233532 | I15: =(precios!H15-precios!H14)/precios!H14 -> -0.0013293497 | ... U15: =(precios!T15-precios!T14)/precios!T14 -> 5.8544683e-05 | V15: =B15-AR$3 -> -0.0057883849 | W15: =C15-AS$3 -> -0.0036642988 | X15: =D15-AT$3 -> -0.017213092 | Y15: =E15-AU$3 -> 0.0080541855 | Z15: =F15-AV$3 -> 0.010451019 | AA15: =G15-AW$3 -> -0.0027765955 | AB15: =H15-AX$3 -> -0.0055275525 | AC15: =I15-AY$3 -> -0.0017454887 | ... AO15: =U15-BK$3 -> 1.0218677e-05
A16: 14 | B16: =(precios!A16-precios!A15)/precios!A15 -> 0.0035693698 | C16: =(precios!B16-precios!B15)/precios!B15 -> 0.0087519527 | D16: =(precios!C16-precios!C15)/precios!C15 -> -0.035816704 | E16: =(precios!D16-precios!D15)/precios!D15 -> -0.0023995495 | F16: =(precios!E16-precios!E15)/precios!E15 -> -0.0043731803 | G16: =(precios!F16-precios!F15)/precios!F15 -> -0.0068328127 | H16: =(precios!G16-precios!G15)/precios!G15 -> 0.0029187673 | I16: =(precios!H16-precios!H15)/precios!H15 -> 0.0017448364 | ... U16: =(precios!T16-precios!T15)/precios!T15 -> 0.00023570595 | V16: =B16-AR$3 -> 0.0024105531 | W16: =C16-AS$3 -> 0.0057571232 | X16: =D16-AT$3 -> -0.037014184 | Y16: =E16-AU$3 -> -0.0033067519 | Z16: =F16-AV$3 -> -0.0054470498 | AA16: =G16-AW$3 -> -0.0070008238 | AB16: =H16-AX$3 -> 0.002414568 | AC16: =I16-AY$3 -> 0.0013286974 | ... AO16: =U16-BK$3 -> 0.00018737994
A17: 15 | B17: =(precios!A17-precios!A16)/precios!A16 -> 0.0048158984 | C17: =(precios!B17-precios!B16)/precios!B16 -> 0.010995156 | D17: =(precios!C17-precios!C16)/precios!C16 -> 0.072392657 | E17: =(precios!D17-precios!D16)/precios!D16 -> -0.0015259112 | F17: =(precios!E17-precios!E16)/precios!E16 -> 0.0031737968 | G17: =(precios!F17-precios!F16)/precios!F16 -> 0.0018885153 | H17: =(precios!G17-precios!G16)/precios!G16 -> -0.0069849839 | I17: =(precios!H17-precios!H16)/precios!H16 -> -0.0045714099 | ... U17: =(precios!T17-precios!T16)/precios!T16 -> 0.00035382494 | V17: =B17-AR$3 -> 0.0036570817 | W17: =C17-AS$3 -> 0.0080003262 | X17: =D17-AT$3 -> 0.071195177 | Y17: =E17-AU$3 -> -0.0024331137 | Z17: =F17-AV$3 -> 0.0020999274 | AA17: =G17-AW$3 -> 0.0017205041 | AB17: =H17-AX$3 -> -0.0074891833 | AC17: =I17-AY$3 -> -0.0049875489 | ... AO17: =U17-BK$3 -> 0.00030549893
A18: 16 | B18: =(precios!A18-precios!A17)/precios!A17 -> -0.002881988 | C18: =(precios!B18-precios!B17)/precios!B17 -> -0.0094123845 | D18: =(precios!C18-precios!C17)/precios!C17 -> 0.010183059 | E18: =(precios!D18-precios!D17)/precios!D17 -> -0.012172427 | F18: =(precios!E18-precios!E17)/precios!E17 -> -0.0075747603 | G18: =(precios!F18-precios!F17)/precios!F17 -> -0.0014137464 | H18: =(precios!G18-precios!G17)/precios!G17 -> -0.01699866 | I18: =(precios!H18-precios!H17)/precios!H17 -> 0.0012001445 | ... U18: =(precios!T18-precios!T17)/precios!T17 -> 0.00035379956 | V18: =B18-AR$3 -> -0.0040408047 | W18: =C18-AS$3 -> -0.012407214 | X18: =D18-AT$3 -> 0.0089855796 | Y18: =E18-AU$3 -> -0.013079629 | Z18: =F18-AV$3 -> -0.0086486298 | AA18: =G18-AW$3 -> -0.0015817575 | AB18: =H18-AX$3 -> -0.017502859 | AC18: =I18-AY$3 -> 0.00078400546 | ... AO18: =U18-BK$3 -> 0.00030547356
A19: 17 | B19: =(precios!A19-precios!A18)/precios!A18 -> -0.029405111 | C19: =(precios!B19-precios!B18)/precios!B18 -> -0.041041001 | D19: =(precios!C19-precios!C18)/precios!C18 -> -0.029108616 | E19: =(precios!D19-precios!D18)/precios!D18 -> -0.017887464 | F19: =(precios!E19-precios!E18)/precios!E18 -> -0.0034140125 | G19: =(precios!F19-precios!F18)/precios!F18 -> 0.0028989237 | H19: =(precios!G19-precios!G18)/precios!G18 -> -0.020572586 | I19: =(precios!H19-precios!H18)/precios!H18 -> 0.0043952548 | ... U19: =(precios!T19-precios!T18)/precios!T18 -> 0.0010603251 | V19: =B19-AR$3 -> -0.030563928 | W19: =C19-AS$3 -> -0.04403583 | X19: =D19-AT$3 -> -0.030306095 | Y19: =E19-AU$3 -> -0.018794666 | Z19: =F19-AV$3 -> -0.004487882 | AA19: =G19-AW$3 -> 0.0027309125 | AB19: =H19-AX$3 -> -0.021076786 | AC19: =I19-AY$3 -> 0.0039791158 | ... AO19: =U19-BK$3 -> 0.0010119991
... A31: 29 | B31: =(precios!A31-precios!A30)/precios!A30 -> 0.023747599 | C31: =(precios!B31-precios!B30)/precios!B30 -> 0.01735774 | D31: =(precios!C31-precios!C30)/precios!C30 -> 0.016912434 | E31: =(precios!D31-precios!D30)/precios!D30 -> 0.0042774696 | F31: =(precios!E31-precios!E30)/precios!E30 -> 0.01429127 | G31: =(precios!F31-precios!F30)/precios!F30 -> -0.005921283 | H31: =(precios!G31-precios!G30)/precios!G30 -> 0.0043138393 | I31: =(precios!H31-precios!H30)/precios!H30 -> -0.0057184214 | ... U31: =(precios!T31-precios!T30)/precios!T30 -> -0.00047096177 | V31: =B31-AR$3 -> 0.022588782 | W31: =C31-AS$3 -> 0.01436291 | X31: =D31-AT$3 -> 0.015714954 | Y31: =E31-AU$3 -> 0.0033702672 | Z31: =F31-AV$3 -> 0.0132174 | AA31: =G31-AW$3 -> -0.0060892941 | AB31: =H31-AX$3 -> 0.0038096399 | AC31: =I31-AY$3 -> -0.0061345604 | ... AO31: =U31-BK$3 -> -0.00051928778
A32: 30 | B32: =(precios!A32-precios!A31)/precios!A31 -> -0.0071207746 | C32: =(precios!B32-precios!B31)/precios!B31 -> -0.0064578373 | D32: =(precios!C32-precios!C31)/precios!C31 -> 0.0036577566 | E32: =(precios!D32-precios!D31)/precios!D31 -> -0.0046898171 | F32: =(precios!E32-precios!E31)/precios!E31 -> 0.0097742124 | G32: =(precios!F32-precios!F31)/precios!F31 -> -0.0066185876 | H32: =(precios!G32-precios!G31)/precios!G31 -> -0.00028606768 | I32: =(precios!H32-precios!H31)/precios!H31 -> 0.012231577 | ... U32: =(precios!T32-precios!T31)/precios!T31 -> 0.00023539261 | V32: =B32-AR$3 -> -0.0082795913 | W32: =C32-AS$3 -> -0.0094526668 | X32: =D32-AT$3 -> 0.002460277 | Y32: =E32-AU$3 -> -0.0055970195 | Z32: =F32-AV$3 -> 0.0087003429 | AA32: =G32-AW$3 -> -0.0067865987 | AB32: =H32-AX$3 -> -0.00079026704 | AC32: =I32-AY$3 -> 0.011815438 | ... AO32: =U32-BK$3 -> 0.0001870666 | AQ32: obs= | AR32: =COUNT(AO3:AO1288) -> 1286
A33: 31 | B33: =(precios!A33-precios!A32)/precios!A32 -> 0.00024618708 | C33: =(precios!B33-precios!B32)/precios!B32 -> 0.070204648 | D33: =(precios!C33-precios!C32)/precios!C32 -> -0.0026219193 | E33: =(precios!D33-precios!D32)/precios!D32 -> -0.0069771661 | F33: =(precios!E33-precios!E32)/precios!E32 -> 0.00034570007 | G33: =(precios!F33-precios!F32)/precios!F32 -> 0.00026641323 | H33: =(precios!G33-precios!G32)/precios!G32 -> -0.0017190764 | I33: =(precios!H33-precios!H32)/precios!H32 -> 0.0094430431 | ... U33: =(precios!T33-precios!T32)/precios!T32 -> 0.00047176994 | V33: =B33-AR$3 -> -0.00091262962 | W33: =C33-AS$3 -> 0.067209819 | X33: =D33-AT$3 -> -0.0038193989 | Y33: =E33-AU$3 -> -0.0078843685 | Z33: =F33-AV$3 -> -0.00072816943 | AA33: =G33-AW$3 -> 9.8402101e-05 | AB33: =H33-AX$3 -> -0.0022232757 | AC33: =I33-AY$3 -> 0.0090269041 | ... AO33: =U33-BK$3 -> 0.00042344394
A34: 32 | B34: =(precios!A34-precios!A33)/precios!A33 -> -0.012114082 | C34: =(precios!B34-precios!B33)/precios!B33 -> 0.012351256 | D34: =(precios!C34-precios!C33)/precios!C33 -> 0.010263837 | E34: =(precios!D34-precios!D33)/precios!D33 -> 0.0016252173 | F34: =(precios!E34-precios!E33)/precios!E33 -> 0.0051144273 | G34: =(precios!F34-precios!F33)/precios!F33 -> -0.0030931169 | H34: =(precios!G34-precios!G33)/precios!G33 -> -0.011502644 | I34: =(precios!H34-precios!H33)/precios!H33 -> -0.0041827226 | ... U34: =(precios!T34-precios!T33)/precios!T33 -> 0.00025005695 | V34: =B34-AR$3 -> -0.013272898 | W34: =C34-AS$3 -> 0.0093564267 | X34: =D34-AT$3 -> 0.009066357 | Y34: =E34-AU$3 -> 0.00071801483 | Z34: =F34-AV$3 -> 0.0040405578 | AA34: =G34-AW$3 -> -0.003261128 | AB34: =H34-AX$3 -> -0.012006843 | AC34: =I34-AY$3 -> -0.0045988616 | ... AO34: =U34-BK$3 -> 0.00020173094 | AQ34: MATRIZ DE VARIANZA-COVARIANZA
A35: 33 | B35: =(precios!A35-precios!A34)/precios!A34 -> -0.006272593 | C35: =(precios!B35-precios!B34)/precios!B34 -> 0.010910196 | D35: =(precios!C35-precios!C34)/precios!C34 -> 0.0090439814 | E35: =(precios!D35-precios!D34)/precios!D34 -> 0.0081046016 | F35: =(precios!E35-precios!E34)/precios!E34 -> 0.0066013426 | G35: =(precios!F35-precios!F34)/precios!F34 -> -0.00351216 | H35: =(precios!G35-precios!G34)/precios!G34 -> -0.0051997591 | I35: =(precios!H35-precios!H34)/precios!H34 -> -0.0059101849 | ... U35: =(precios!T35-precios!T34)/precios!T34 -> 0.00010310504 | V35: =B35-AR$3 -> -0.0074314097 | W35: =C35-AS$3 -> 0.0079153661 | X35: =D35-AT$3 -> 0.0078465018 | Y35: =E35-AU$3 -> 0.0071973992 | Z35: =F35-AV$3 -> 0.0055274731 | AA35: =G35-AW$3 -> -0.0036801711 | AB35: =H35-AX$3 -> -0.0057039584 | AC35: =I35-AY$3 -> -0.0063263239 | ... AO35: =U35-BK$3 -> 5.477903e-05
A36: 34 | B36: =(precios!A36-precios!A35)/precios!A35 -> 0.014482767 | C36: =(precios!B36-precios!B35)/precios!B35 -> 0.061132425 | D36: =(precios!C36-precios!C35)/precios!C35 -> -0.0041002536 | E36: =(precios!D36-precios!D35)/precios!D35 -> 0.0067496501 | F36: =(precios!E36-precios!E35)/precios!E35 -> 0.0030118906 | G36: =(precios!F36-precios!F35)/precios!F35 -> -0.0013407885 | H36: =(precios!G36-precios!G35)/precios!G35 -> 0.013131098 | I36: =(precios!H36-precios!H35)/precios!H35 -> 0.004564876 | ... U36: =(precios!T36-precios!T35)/precios!T35 -> 0.00011791988 | V36: =B36-AR$3 -> 0.01332395 | W36: =C36-AS$3 -> 0.058137596 | X36: =D36-AT$3 -> -0.0052977332 | Y36: =E36-AU$3 -> 0.0058424477 | Z36: =F36-AV$3 -> 0.0019380211 | AA36: =G36-AW$3 -> -0.0015087996 | AB36: =H36-AX$3 -> 0.012626898 | AC36: =I36-AY$3 -> 0.0041487369 | ... AO36: =U36-BK$3 -> 6.9593875e-05
A37: 35 | B37: =(precios!A37-precios!A36)/precios!A36 -> -0.010258949 | C37: =(precios!B37-precios!B36)/precios!B36 -> -0.019065854 | D37: =(precios!C37-precios!C36)/precios!C36 -> -0.00049199213 | E37: =(precios!D37-precios!D36)/precios!D36 -> -0.0078886269 | F37: =(precios!E37-precios!E36)/precios!E36 -> 0.0032812566 | G37: =(precios!F37-precios!F36)/precios!F36 -> -0.0038272731 | H37: =(precios!G37-precios!G36)/precios!G36 -> 0.0037439948 | I37: =(precios!H37-precios!H36)/precios!H36 -> 0.009087921 | ... U37: =(precios!T37-precios!T36)/precios!T36 -> 0.00023521496 | V37: =B37-AR$3 -> -0.011417766 | W37: =C37-AS$3 -> -0.022060683 | X37: =D37-AT$3 -> -0.0016894718 | Y37: =E37-AU$3 -> -0.0087958293 | Z37: =F37-AV$3 -> 0.0022073871 | AA37: =G37-AW$3 -> -0.0039952843 | AB37: =H37-AX$3 -> 0.0032397955 | AC37: =I37-AY$3 -> 0.008671782 | ... AO37: =U37-BK$3 -> 0.00018688896
A38: 36 | B38: =(precios!A38-precios!A37)/precios!A37 -> -0.022634925 | C38: =(precios!B38-precios!B37)/precios!B37 -> -0.047392298 | D38: =(precios!C38-precios!C37)/precios!C37 -> -0.015362675 | E38: =(precios!D38-precios!D37)/precios!D37 -> -0.026533823 | F38: =(precios!E38-precios!E37)/precios!E37 -> -0.0065722704 | G38: =(precios!F38-precios!F37)/precios!F37 -> 0.01051414 | H38: =(precios!G38-precios!G37)/precios!G37 -> -0.014060067 | I38: =(precios!H38-precios!H37)/precios!H37 -> 0.00094800066 | ... U38: =(precios!T38-precios!T37)/precios!T37 -> 0.00082365563 | V38: =B38-AR$3 -> -0.023793741 | W38: =C38-AS$3 -> -0.050387127 | X38: =D38-AT$3 -> -0.016560155 | Y38: =E38-AU$3 -> -0.027441026 | Z38: =F38-AV$3 -> -0.0076461399 | AA38: =G38-AW$3 -> 0.010346129 | AB38: =H38-AX$3 -> -0.014564266 | AC38: =I38-AY$3 -> 0.00053186166 | ... AO38: =U38-BK$3 -> 0.00077532962
A39: 37 | B39: =(precios!A39-precios!A38)/precios!A38 -> -0.047500469 | C39: =(precios!B39-precios!B38)/precios!B38 -> -0.070697427 | D39: =(precios!C39-precios!C38)/precios!C38 -> -0.029915528 | E39: =(precios!D39-precios!D38)/precios!D38 -> -0.04135555 | F39: =(precios!E39-precios!E38)/precios!E38 -> -0.025873421 | G39: =(precios!F39-precios!F38)/precios!F38 -> -0.020606781 | H39: =(precios!G39-precios!G38)/precios!G38 -> -0.047439024 | I39: =(precios!H39-precios!H38)/precios!H38 -> -0.026835034 | ... U39: =(precios!T39-precios!T38)/precios!T38 -> 0.0016469495 | V39: =B39-AR$3 -> -0.048659286 | W39: =C39-AS$3 -> -0.073692256 | X39: =D39-AT$3 -> -0.031113008 | Y39: =E39-AU$3 -> -0.042262753 | Z39: =F39-AV$3 -> -0.02694729 | AA39: =G39-AW$3 -> -0.020774792 | AB39: =H39-AX$3 -> -0.047943223 | AC39: =I39-AY$3 -> -0.027251173 | ... AO39: =U39-BK$3 -> 0.0015986235
A40: 38 | B40: =(precios!A40-precios!A39)/precios!A39 -> -0.033872254 | C40: =(precios!B40-precios!B39)/precios!B39 -> -0.04109342 | D40: =(precios!C40-precios!C39)/precios!C39 -> -0.023352361 | E40: =(precios!D40-precios!D39)/precios!D39 -> -0.018190499 | F40: =(precios!E40-precios!E39)/precios!E39 -> -0.027900059 | G40: =(precios!F40-precios!F39)/precios!F39 -> -0.0086352528 | H40: =(precios!G40-precios!G39)/precios!G39 -> -0.050412444 | I40: =(precios!H40-precios!H39)/precios!H39 -> -0.015166256 | ... U40: =(precios!T40-precios!T39)/precios!T39 -> 0.0010564028 | V40: =B40-AR$3 -> -0.035031071 | W40: =C40-AS$3 -> -0.044088249 | X40: =D40-AT$3 -> -0.024549841 | Y40: =E40-AU$3 -> -0.019097701 | Z40: =F40-AV$3 -> -0.028973929 | AA40: =G40-AW$3 -> -0.0088032639 | AB40: =H40-AX$3 -> -0.050916643 | AC40: =I40-AY$3 -> -0.015582395 | ... AO40: =U40-BK$3 -> 0.0010080768
A41: 39 | B41: =(precios!A41-precios!A40)/precios!A40 -> 0.015863923 | C41: =(precios!B41-precios!B40)/precios!B40 -> 0.021370066 | D41: =(precios!C41-precios!C40)/precios!C40 -> 0.053181133 | E41: =(precios!D41-precios!D40)/precios!D40 -> 0.0034723154 | F41: =(precios!E41-precios!E40)/precios!E40 -> 0.0026899022 | G41: =(precios!F41-precios!F40)/precios!F40 -> -0.0067057722 | H41: =(precios!G41-precios!G40)/precios!G40 -> -0.014478573 | I41: =(precios!H41-precios!H40)/precios!H40 -> -0.010458638 | ... U41: =(precios!T41-precios!T40)/precios!T40 -> 0.00070359144 | V41: =B41-AR$3 -> 0.014705107 | W41: =C41-AS$3 -> 0.018375236 | X41: =D41-AT$3 -> 0.051983653 | Y41: =E41-AU$3 -> 0.002565113 | Z41: =F41-AV$3 -> 0.0016160327 | AA41: =G41-AW$3 -> -0.0068737833 | AB41: =H41-AX$3 -> -0.014982773 | AC41: =I41-AY$3 -> -0.010874777 | ... AO41: =U41-BK$3 -> 0.00065526543
A42: 40 | B42: =(precios!A42-precios!A41)/precios!A41 -> -0.065368696 | C42: =(precios!B42-precios!B41)/precios!B41 -> -0.055665759 | D42: =(precios!C42-precios!C41)/precios!C41 -> -0.019855498 | E42: =(precios!D42-precios!D41)/precios!D41 -> -0.048136265 | F42: =(precios!E42-precios!E41)/precios!E41 -> -0.041087494 | G42: =(precios!F42-precios!F41)/precios!F41 -> -0.03173729 | H42: =(precios!G42-precios!G41)/precios!G41 -> -0.048971603 | I42: =(precios!H42-precios!H41)/precios!H41 -> -0.055426286 | ... U42: =(precios!T42-precios!T41)/precios!T41 -> 0.0011724222 | V42: =B42-AR$3 -> -0.066527513 | W42: =C42-AS$3 -> -0.058660588 | X42: =D42-AT$3 -> -0.021052977 | Y42: =E42-AU$3 -> -0.049043468 | Z42: =F42-AV$3 -> -0.042161364 | AA42: =G42-AW$3 -> -0.031905301 | AB42: =H42-AX$3 -> -0.049475803 | AC42: =I42-AY$3 -> -0.055842425 | ... AO42: =U42-BK$3 -> 0.0011240962
A43: 41 | B43: =(precios!A43-precios!A42)/precios!A42 -> -0.00058469672 | C43: =(precios!B43-precios!B42)/precios!B42 -> 0.069160964 | D43: =(precios!C43-precios!C42)/precios!C42 -> -0.0072099022 | E43: =(precios!D43-precios!D42)/precios!D42 -> -0.00029184672 | F43: =(precios!E43-precios!E42)/precios!E42 -> -0.040903441 | G43: =(precios!F43-precios!F42)/precios!F42 -> -0.033352483 | H43: =(precios!G43-precios!G42)/precios!G42 -> -0.021627272 | I43: =(precios!H43-precios!H42)/precios!H42 -> -0.0023788899 | ... U43: =(precios!T43-precios!T42)/precios!T42 -> 0.0036295008 | V43: =B43-AR$3 -> -0.0017435134 | W43: =C43-AS$3 -> 0.066166134 | X43: =D43-AT$3 -> -0.0084073818 | Y43: =E43-AU$3 -> -0.0011990491 | Z43: =F43-AV$3 -> -0.04197731 | AA43: =G43-AW$3 -> -0.033520494 | AB43: =H43-AX$3 -> -0.022131472 | AC43: =I43-AY$3 -> -0.0027950289 | ... AO43: =U43-BK$3 -> 0.0035811748
A44: 42 | B44: =(precios!A44-precios!A43)/precios!A43 -> 0.093100982 | C44: =(precios!B44-precios!B43)/precios!B43 -> 0.023549294 | D44: =(precios!C44-precios!C43)/precios!C43 -> 0.032571848 | E44: =(precios!D44-precios!D43)/precios!D43 -> 0.037266114 | F44: =(precios!E44-precios!E43)/precios!E43 -> 0.099594488 | G44: =(precios!F44-precios!F43)/precios!F43 -> 0.041195479 | H44: =(precios!G44-precios!G43)/precios!G43 -> 0.03052624 | I44: =(precios!H44-precios!H43)/precios!H43 -> 0.055904022 | ... U44: =(precios!T44-precios!T43)/precios!T43 -> -0.00040960743 | V44: =B44-AR$3 -> 0.091942165 | W44: =C44-AS$3 -> 0.020554464 | X44: =D44-AT$3 -> 0.031374368 | Y44: =E44-AU$3 -> 0.036358912 | Z44: =F44-AV$3 -> 0.098520618 | AA44: =G44-AW$3 -> 0.041027468 | AB44: =H44-AX$3 -> 0.030022041 | AC44: =I44-AY$3 -> 0.055487883 | ... AO44: =U44-BK$3 -> -0.00045793344
A45: 43 | B45: =(precios!A45-precios!A44)/precios!A44 -> -0.031759522 | C45: =(precios!B45-precios!B44)/precios!B44 -> -0.038128858 | D45: =(precios!C45-precios!C44)/precios!C44 -> -0.03222674 | E45: =(precios!D45-precios!D44)/precios!D44 -> -0.023009811 | F45: =(precios!E45-precios!E44)/precios!E44 -> -0.020735129 | G45: =(precios!F45-precios!F44)/precios!F44 -> -0.031638226 | H45: =(precios!G45-precios!G44)/precios!G44 -> -0.055158114 | I45: =(precios!H45-precios!H44)/precios!H44 -> -0.011625882 | ... U45: =(precios!T45-precios!T44)/precios!T44 -> 0.003973686 | V45: =B45-AR$3 -> -0.032918339 | W45: =C45-AS$3 -> -0.041123687 | X45: =D45-AT$3 -> -0.033424219 | Y45: =E45-AU$3 -> -0.023917014 | Z45: =F45-AV$3 -> -0.021808999 | AA45: =G45-AW$3 -> -0.031806237 | AB45: =H45-AX$3 -> -0.055662313 | AC45: =I45-AY$3 -> -0.012042021 | ... AO45: =U45-BK$3 -> 0.00392536
A46: 44 | B46: =(precios!A46-precios!A45)/precios!A45 -> 0.046384513 | C46: =(precios!B46-precios!B45)/precios!B45 -> 0.070028967 | D46: =(precios!C46-precios!C45)/precios!C45 -> 0.040730048 | E46: =(precios!D46-precios!D45)/precios!D45 -> 0.035013229 | F46: =(precios!E46-precios!E45)/precios!E45 -> 0.059492307 | G46: =(precios!F46-precios!F45)/precios!F45 -> 0.058190097 | H46: =(precios!G46-precios!G45)/precios!G45 -> 0.02306277 | I46: =(precios!H46-precios!H45)/precios!H45 -> 0.053566844 | ... U46: =(precios!T46-precios!T45)/precios!T45 -> 0.00011630653 | V46: =B46-AR$3 -> 0.045225696 | W46: =C46-AS$3 -> 0.067034137 | X46: =D46-AT$3 -> 0.039532569 | Y46: =E46-AU$3 -> 0.034106027 | Z46: =F46-AV$3 -> 0.058418437 | AA46: =G46-AW$3 -> 0.058022086 | AB46: =H46-AX$3 -> 0.022558571 | AC46: =I46-AY$3 -> 0.053150705 | ... AO46: =U46-BK$3 -> 6.7980522e-05
... A56: 54 | B56: =(precios!A56-precios!A55)/precios!A55 -> -0.024479933 | C56: =(precios!B56-precios!B55)/precios!B55 -> -0.066506834 | D56: =(precios!C56-precios!C55)/precios!C55 -> -0.013385454 | E56: =(precios!D56-precios!D55)/precios!D55 -> 0.012257741 | F56: =(precios!E56-precios!E55)/precios!E55 -> 0.0016615153 | G56: =(precios!F56-precios!F55)/precios!F55 -> -0.011933286 | H56: =(precios!G56-precios!G55)/precios!G55 -> -0.054140095 | I56: =(precios!H56-precios!H55)/precios!H55 -> -0.0066811873 | ... U56: =(precios!T56-precios!T55)/precios!T55 -> -0.0012757507 | V56: =B56-AR$3 -> -0.02563875 | W56: =C56-AS$3 -> -0.069501664 | X56: =D56-AT$3 -> -0.014582933 | Y56: =E56-AU$3 -> 0.011350539 | Z56: =F56-AV$3 -> 0.00058764582 | AA56: =G56-AW$3 -> -0.012101297 | AB56: =H56-AX$3 -> -0.054644294 | AC56: =I56-AY$3 -> -0.0070973263 | ... AO56: =U56-BK$3 -> -0.0013240767
A57: 55 | B57: =(precios!A57-precios!A56)/precios!A56 -> -0.0076621328 | C57: =(precios!B57-precios!B56)/precios!B56 -> 0.050044183 | D57: =(precios!C57-precios!C56)/precios!C56 -> 0.052493098 | E57: =(precios!D57-precios!D56)/precios!D56 -> 0.027830614 | F57: =(precios!E57-precios!E56)/precios!E56 -> -0.0074148999 | G57: =(precios!F57-precios!F56)/precios!F56 -> -0.058610026 | H57: =(precios!G57-precios!G56)/precios!G56 -> 0.019721015 | I57: =(precios!H57-precios!H56)/precios!H56 -> -0.056364343 | ... U57: =(precios!T57-precios!T56)/precios!T56 -> 0.0017418198 | V57: =B57-AR$3 -> -0.0088209495 | W57: =C57-AS$3 -> 0.047049354 | X57: =D57-AT$3 -> 0.051295618 | Y57: =E57-AU$3 -> 0.026923411 | Z57: =F57-AV$3 -> -0.0084887694 | AA57: =G57-AW$3 -> -0.058778037 | AB57: =H57-AX$3 -> 0.019216816 | AC57: =I57-AY$3 -> -0.056780482 | ... AO57: =U57-BK$3 -> 0.0016934938 | AQ57: RIESGO Y RENDIMIENTO DEL PORTAFOLIO
A58: 56 | B58: =(precios!A58-precios!A57)/precios!A57 -> -0.063485342 | C58: =(precios!B58-precios!B57)/precios!B57 -> -0.03390145 | D58: =(precios!C58-precios!C57)/precios!C57 -> 0.0024093841 | E58: =(precios!D58-precios!D57)/precios!D57 -> -0.018522799 | F58: =(precios!E58-precios!E57)/precios!E57 -> -0.048489237 | G58: =(precios!F58-precios!F57)/precios!F57 -> -0.056355746 | H58: =(precios!G58-precios!G57)/precios!G57 -> -0.072169911 | I58: =(precios!H58-precios!H57)/precios!H57 -> -0.075791451 | ... U58: =(precios!T58-precios!T57)/precios!T57 -> 0.0026668378 | V58: =B58-AR$3 -> -0.064644159 | W58: =C58-AS$3 -> -0.036896279 | X58: =D58-AT$3 -> 0.0012119044 | Y58: =E58-AU$3 -> -0.019430001 | Z58: =F58-AV$3 -> -0.049563106 | AA58: =G58-AW$3 -> -0.056523757 | AB58: =H58-AX$3 -> -0.07267411 | AC58: =I58-AY$3 -> -0.07620759 | ... AO58: =U58-BK$3 -> 0.0026185118 | AQ58: Vector de Proporciones
A59: 57 | B59: =(precios!A59-precios!A58)/precios!A58 -> -0.021244242 | C59: =(precios!B59-precios!B58)/precios!B58 -> 0.033730137 | D59: =(precios!C59-precios!C58)/precios!C58 -> 0.082444502 | E59: =(precios!D59-precios!D58)/precios!D58 -> 0.030735292 | F59: =(precios!E59-precios!E58)/precios!E58 -> -0.016837691 | G59: =(precios!F59-precios!F58)/precios!F58 -> -0.072983673 | H59: =(precios!G59-precios!G58)/precios!G58 -> -0.080833744 | I59: =(precios!H59-precios!H58)/precios!H58 -> -0.046178354 | ... U59: =(precios!T59-precios!T58)/precios!T58 -> 0.0011556556 | V59: =B59-AR$3 -> -0.022403059 | W59: =C59-AS$3 -> 0.030735308 | X59: =D59-AT$3 -> 0.081247022 | Y59: =E59-AU$3 -> 0.029828089 | Z59: =F59-AV$3 -> -0.01791156 | AA59: =G59-AW$3 -> -0.073151684 | AB59: =H59-AX$3 -> -0.081337943 | AC59: =I59-AY$3 -> -0.046594493 | ... AO59: =U59-BK$3 -> 0.0011073296 | AQ59: w= | AR59: 0.05 | AS59: 0.05 | AT59: 0.05 | AU59: 0.05 | AV59: 0.05 | AW59: 0.05 | AX59: 0.05 | AY59: 0.05 | AZ59: 0.05 | BA59: 0.05 | BB59: 0.05 | BC59: 0.05 | BD59: 0.05 | BE59: 0.05 | BF59: 0.1 | BG59: 0.1 | BH59: 0.025 | BI59: 0.025 | BJ59: 0.025 | BK59: 0.025 | BL59: =+SUM(AR59:BK59) -> 1
A60: 58 | B60: =(precios!A60-precios!A59)/precios!A59 -> 0.10032534 | C60: =(precios!B60-precios!B59)/precios!B59 -> 0.17156423 | D60: =(precios!C60-precios!C59)/precios!C59 -> -0.0081882526 | E60: =(precios!D60-precios!D59)/precios!D59 -> 0.019586561 | F60: =(precios!E60-precios!E59)/precios!E59 -> -0.0020666191 | G60: =(precios!F60-precios!F59)/precios!F59 -> 0.072341167 | H60: =(precios!G60-precios!G59)/precios!G59 -> 0.16316375 | I60: =(precios!H60-precios!H59)/precios!H59 -> 0.057011458 | ... U60: =(precios!T60-precios!T59)/precios!T59 -> -0.00138618 | V60: =B60-AR$3 -> 0.099166523 | W60: =C60-AS$3 -> 0.1685694 | X60: =D60-AT$3 -> -0.0093857323 | Y60: =E60-AU$3 -> 0.018679359 | Z60: =F60-AV$3 -> -0.0031404886 | AA60: =G60-AW$3 -> 0.072173156 | AB60: =H60-AX$3 -> 0.16265955 | AC60: =I60-AY$3 -> 0.056595319 | ... AO60: =U60-BK$3 -> -0.001434506
...
